Workbook

Sheet Assumptions
A1: BETA DRUGS LTD — KEY ASSUMPTIONS
A2: Consolidated | All figures in ₹ Crores unless stated otherwise
A4: 1. REVENUE ASSUMPTIONS
A5: Assumption | B5: FY21A | C5: FY22A | D5: FY23A | E5: FY24A | F5: FY25A | G5: FY26E | H5: FY27E | I5: FY28E | J5: FY29E | K5: FY30E
A6: Revenue from Operations (₹ Cr) | B6: 91.2 | C6: 184 | D6: 227.1 | E6: 297.1 | F6: 368.8 | G6: 400 | H6: 545 | I6: 720 | J6: 920 | K6: 1140
A7: Revenue Growth (%) | B7: 0.28 | C7: 0.58 | D7: 0.234 | E7: 0.308 | F7: 0.241 | G7: 0.085 | H7: 0.3625 | I7: 0.321 | J7: 0.278 | K7: 0.239
A9: Revenue Mix:
A10: Own Brands (₹ Cr) | B10: 42 | C10: 72 | D10: 82 | E10: 100 | F10: 125.3 | G10: 175 | H10: 240 | I10: 310 | J10: 390 | K10: 470
A11: CDMO / Contract Mfg (₹ Cr) | B11: 38 | C11: 75 | D11: 90 | E11: 105 | F11: 110 | G11: 65 | H11: 75 | I11: 85 | J11: 95 | K11: 105
A12: Exports (₹ Cr) | B12: 5 | C12: 20 | D12: 30 | E12: 46 | F12: 80 | G12: 85 | H12: 140 | I12: 210 | J12: 300 | K12: 390
A13: API Sales (₹ Cr) | B13: 4 | C13: 12 | D13: 18 | E13: 28 | F13: 35 | G13: 15 | H13: 20 | I13: 25 | J13: 30 | K13: 35
A14: Derma/Cosmetology (₹ Cr) | B14: 0 | C14: 0 | D14: 3 | E14: 10 | F14: 15 | G14: 17 | H14: 22 | I14: 28 | J14: 35 | K14: 42
A15: IVF / Nivian Life Sciences (₹ Cr) | B15: 0 | C15: 0 | D15: 0 | E15: 0 | F15: 0 | G15: 43 | H15: 48 | I15: 62 | J15: 70 | K15: 98
A16: Other Income (₹ Cr) | B16: 2.2 | C16: 5 | D16: 4.1 | E16: 8.1 | F16: 3.5 | G16: 0 | H16: 0 | I16: 0 | J16: 0 | K16: 0
A19: 2. MARGIN & COST ASSUMPTIONS
A20: Assumption | B20: FY21A | C20: FY22A | D20: FY23A | E20: FY24A | F20: FY25A | G20: FY26E | H20: FY27E | I20: FY28E | J20: FY29E | K20: FY30E
A21: COGS / Material Cost (% of Rev) | B21: 0.51 | C21: 0.51 | D21: 0.465 | E21: 0.5 | F21: 0.48 | G21: 0.47 | H21: 0.455 | I21: 0.44 | J21: 0.43 | K21: 0.42
A22: Employee Cost (% of Rev) | B22: 0.1 | C22: 0.09 | D22: 0.095 | E22: 0.11 | F22: 0.105 | G22: 0.125 | H22: 0.115 | I22: 0.105 | J22: 0.095 | K22: 0.09
A23: Other Expenses (% of Rev) | B23: 0.18 | C23: 0.17 | D23: 0.17 | E23: 0.19 | F23: 0.185 | G23: 0.185 | H23: 0.185 | I23: 0.175 | J23: 0.17 | K23: 0.165
A24: EBITDA Margin (%) | B24: 0.21 | C24: 0.23 | D24: 0.234 | E24: 0.203 | F24: 0.2237 | G24: 0.22 | H24: 0.245 | I24: 0.28 | J24: 0.305 | K24: 0.325
A25: Depreciation (% of Rev) | B25: 0.06 | C25: 0.035 | D25: 0.035 | E25: 0.028 | F25: 0.027 | G25: 0.03 | H25: 0.028 | I25: 0.026 | J25: 0.025 | K25: 0.023
A26: Finance Cost (% of Rev) | B26: 0.02 | C26: 0.01 | D26: 0.01 | E26: 0.01 | F26: 0.025 | G26: 0.015 | H26: 0.012 | I26: 0.01 | J26: 0.008 | K26: 0.007
A27: Effective Tax Rate (%) | B27: 0.22 | C27: 0.22 | D27: 0.225 | E27: 0.225 | F27: 0.22 | G27: 0.225 | H27: 0.225 | I27: 0.225 | J27: 0.225 | K27: 0.225
A28: Net Profit Margin (%) | B28: 0.1 | C28: 0.14 | D28: 0.135 | E28: 0.123 | F28: 0.114 | G28: 0.125 | H28: 0.155 | I28: 0.185 | J28: 0.21 | K28: 0.235
A31: 3. BALANCE SHEET & WORKING CAPITAL ASSUMPTIONS
A32: Assumption | B32: FY21A | C32: FY22A | D32: FY23A | E32: FY24A | F32: FY25A | G32: FY26E | H32: FY27E | I32: FY28E | J32: FY29E | K32: FY30E
A33: Debtor Days | B33: 150 | C33: 132 | D33: 135 | E33: 125 | F33: 122 | G33: 118 | H33: 112 | I33: 105 | J33: 100 | K33: 95
A34: Inventory Days | B34: 90 | C34: 85 | D34: 95 | E34: 100 | F34: 105 | G34: 100 | H34: 92 | I34: 85 | J34: 80 | K34: 75
A35: Creditor Days | B35: 80 | C35: 70 | D35: 75 | E35: 72 | F35: 70 | G35: 70 | H35: 68 | I35: 65 | J35: 62 | K35: 60
A36: Capex (₹ Cr) | B36: 8 | C36: 12 | D36: 19 | E36: 14 | F36: 25 | G36: 35 | H36: 42 | I36: 48 | J36: 52 | K36: 55
A37: Capex (% of Rev) | B37: 0.088 | C37: 0.065 | D37: 0.084 | E37: 0.047 | F37: 0.068 | G37: 0.088 | H37: 0.077 | I37: 0.067 | J37: 0.057 | K37: 0.048
A38: Equity Shares Outstanding (Cr) | B38: 0.96 | C38: 0.96 | D38: 0.96 | E38: 0.96 | F38: 1.01 | G38: 1.0384 | H38: 1.0384 | I38: 1.0384 | J38: 1.0384 | K38: 1.0384
A42: 4. RATIONALE & KEY NOTES
A43: • FY26E: Mgmt guided ₹400 Cr (revised DOWN from ₹420 Cr). Q3 revenue dipped to ₹89.58 Cr due to: (a) strategic exit from Platin CDMO (~₹46.5 Cr FY25), (b) export tender delays. This is STRUCTURAL, not seasonal.
A44: • FY26E Nivian Contribution: ₹43 Cr (9M actual ₹30.3 Cr). 66.09% stake acquired for ₹69.4 Cr. SCUTTLEBUTT: Gynecologists actively using Nivian products - confirms market adoption before financial data shows it.
A45: • FY27E: Mgmt targets ₹530 Cr with 24% EBITDA margin. Growth drivers: NDDS launches (Methotrexate Oral ~₹13 Cr), export ramp-up (EU-GMP/ANVISA/COFEPRIS approvals), Nivian cross-selling via Beta's gynec distribution network.
A46: • FY28E-FY30E: Revenue doubling target (₹750 Cr by FY28). We model ~₹720 Cr, slightly conservative. Long-term growth tapers from 32% → 24% as base effect kicks in.
A47: • Export thesis: CAGR was 64% (FY20-FY25). We assume 25-35% forward growth as regulated market registrations (EU, LatAm, Africa) come through. 21% employee cost increase in FY26 is INVESTMENT for regulatory teams.
A49: Margin Expansion Rationale:
A50: • EBITDA margins guided 23-25% range. Q3 FY26 EBITDA was 21.5% but gross margin hit 59% (up from 52% YoY) — product mix shift is WORKING. Operating leverage temporarily hit by employee hiring.
...

Sheet Income Statement
A1: BETA DRUGS LTD — CONSOLIDATED INCOME STATEMENT
A2: All figures in ₹ Crores | Year ending March
A4: Particulars | C4: FY21A | D4: FY22A | E4: FY23A | F4: FY24A | G4: FY25A | H4: FY26E | I4: FY27E | J4: FY28E | K4: FY29E | L4: FY30E
A5: Revenue from Operations | C5: 91.2 | D5: 184 | E5: 227.1 | F5: 297.1 | G5: 368.8 | H5: =Assumptions!G6 -> 400 | I5: =Assumptions!H6 -> 545 | J5: =Assumptions!I6 -> 720 | K5: =Assumptions!J6 -> 920 | L5: =Assumptions!K6 -> 1140
A6: YoY Growth (%) | C6: 0.28 | D6: 0.58 | E6: 0.234 | F6: 0.308 | G6: 0.241 | H6: =(H5-G5)/G5 -> 0.084598698 | I6: =(I5-H5)/H5 -> 0.3625 | J6: =(J5-I5)/I5 -> 0.32110092 | K6: =(K5-J5)/J5 -> 0.27777778 | L6: =(L5-K5)/K5 -> 0.23913043
A7: Other Income | C7: 2.2 | D7: 5 | E7: 4.1 | F7: 8.1 | G7: 17.2 | H7: 10 | I7: 12 | J7: 14 | K7: 16 | L7: 18
A8: Total Income | C8: =C5+C7 -> 93.4 | D8: =D5+D7 -> 189 | E8: =E5+E7 -> 231.2 | F8: =F5+F7 -> 305.2 | G8: =G5+G7 -> 386 | H8: =H5+H7 -> 410 | I8: =I5+I7 -> 557 | J8: =J5+J7 -> 734 | ... L8: =L5+L7 -> 1158
A10: EXPENSES:
A11: Cost of Materials / COGS | C11: 46.5 | D11: 93.8 | E11: 105.6 | F11: 148.6 | G11: 177 | H11: =H5*Assumptions!G21 -> 188 | I11: =I5*Assumptions!H21 -> 247.975 | J11: =J5*Assumptions!I21 -> 316.8 | K11: =K5*Assumptions!J21 -> 395.6 | L11: =L5*Assumptions!K21 -> 478.8
A12: % of Revenue | C12: =C11/C5 -> 0.50986842 | D12: =D11/D5 -> 0.50978261 | E12: =E11/E5 -> 0.46499339 | F12: =F11/F5 -> 0.50016829 | G12: =G11/G5 -> 0.47993492 | H12: =H11/H5 -> 0.47 | I12: =I11/I5 -> 0.455 | J12: =J11/J5 -> 0.44 | ... L12: =L11/L5 -> 0.42
A13: Employee Benefit Expense | C13: 9.1 | D13: 16.6 | E13: 21.6 | F13: 32.7 | G13: 38.7 | H13: =H5*Assumptions!G22 -> 50 | I13: =I5*Assumptions!H22 -> 62.675 | J13: =J5*Assumptions!I22 -> 75.6 | K13: =K5*Assumptions!J22 -> 87.4 | L13: =L5*Assumptions!K22 -> 102.6
A14: Other Expenses | C14: 16.4 | D14: 31.3 | E14: 38.6 | F14: 56.4 | G14: 68.2 | H14: =H5*Assumptions!G23 -> 74 | I14: =I5*Assumptions!H23 -> 100.825 | J14: =J5*Assumptions!I23 -> 126 | K14: =K5*Assumptions!J23 -> 156.4 | L14: =L5*Assumptions!K23 -> 188.1
A15: Total Operating Expenses | C15: =C11+C13+C14 -> 72 | D15: =D11+D13+D14 -> 141.7 | E15: =E11+E13+E14 -> 165.8 | F15: =F11+F13+F14 -> 237.7 | G15: =G11+G13+G14 -> 283.9 | H15: =H11+H13+H14 -> 312 | I15: =I11+I13+I14 -> 411.475 | J15: =J11+J13+J14 -> 518.4 | ... L15: =L11+L13+L14 -> 769.5
A17: EBITDA | C17: =C5-C15 -> 19.2 | D17: =D5-D15 -> 42.3 | E17: =E5-E15 -> 61.3 | F17: =F5-F15 -> 59.4 | G17: =G5-G15 -> 84.9 | H17: =H5-H15 -> 88 | I17: =I5-I15 -> 133.525 | J17: =J5-J15 -> 201.6 | ... L17: =L5-L15 -> 370.5
A18: EBITDA Margin (%) | C18: =C17/C5 -> 0.21052632 | D18: =D17/D5 -> 0.2298913 | E18: =E17/E5 -> 0.26992514 | F18: =F17/F5 -> 0.19993268 | G18: =G17/G5 -> 0.23020607 | H18: =H17/H5 -> 0.22 | I18: =I17/I5 -> 0.245 | J18: =J17/J5 -> 0.28 | ... L18: =L17/L5 -> 0.325
A20: Depreciation & Amortization | C20: 5.5 | D20: 6.4 | E20: 8 | F20: 8.3 | G20: 10 | H20: =H5*Assumptions!G25 -> 12 | I20: =I5*Assumptions!H25 -> 15.26 | J20: =J5*Assumptions!I25 -> 18.72 | K20: =K5*Assumptions!J25 -> 23 | L20: =L5*Assumptions!K25 -> 26.22
A21: Finance Cost | C21: 1.8 | D21: 1.8 | E21: 2.3 | F21: 3 | G21: 9.2 | H21: =H5*Assumptions!G26 -> 6 | I21: =I5*Assumptions!H26 -> 6.54 | J21: =J5*Assumptions!I26 -> 7.2 | K21: =K5*Assumptions!J26 -> 7.36 | L21: =L5*Assumptions!K26 -> 7.98
A22: Profit Before Tax (PBT) | C22: =C17-C20-C21+C7 -> 14.1 | D22: =D17-D20-D21+D7 -> 39.1 | E22: =E17-E20-E21+E7 -> 55.1 | F22: =F17-F20-F21+F7 -> 56.2 | G22: =G17-G20-G21+G7 -> 82.9 | H22: =H17-H20-H21+H7 -> 80 | I22: =I17-I20-I21+I7 -> 123.725 | J22: =J17-J20-J21+J7 -> 189.68 | ... L22: =L17-L20-L21+L7 -> 354.3
A23: Tax Expense | C23: 3.8 | D23: 8.6 | E23: 8.8 | F23: 10.5 | G23: 10.3 | H23: =H22*Assumptions!G27 -> 18 | I23: =I22*Assumptions!H27 -> 27.838125 | J23: =J22*Assumptions!I27 -> 42.678 | K23: =K22*Assumptions!J27 -> 59.904 | L23: =L22*Assumptions!K27 -> 79.7175
A24: Effective Tax Rate (%) | C24: =C23/C22 -> 0.26950355 | D24: =D23/D22 -> 0.21994885 | E24: =E23/E22 -> 0.15970962 | F24: =F23/F22 -> 0.18683274 | G24: =G23/G22 -> 0.12424608 | H24: =H23/H22 -> 0.225 | I24: =I23/I22 -> 0.225 | J24: =J23/J22 -> 0.225 | ... L24: =L23/L22 -> 0.225
A26: NET PROFIT (PAT) | C26: =C22-C23 -> 10.3 | D26: =D22-D23 -> 30.5 | E26: =E22-E23 -> 46.3 | F26: =F22-F23 -> 45.7 | G26: =G22-G23 -> 72.6 | H26: =H22-H23 -> 62 | I26: =I22-I23 -> 95.886875 | J26: =J22-J23 -> 147.002 | ... L26: =L22-L23 -> 274.5825
A27: Net Profit Margin (%) | C27: =C26/C5 -> 0.1129386 | D27: =D26/D5 -> 0.16576087 | E27: =E26/E5 -> 0.20387494 | F27: =F26/F5 -> 0.15382026 | G27: =G26/G5 -> 0.19685466 | H27: =H26/H5 -> 0.155 | I27: =I26/I5 -> 0.17593922 | J27: =J26/J5 -> 0.20416944 | ... L27: =L26/L5 -> 0.24086184
A29: EPS (₹) | C29: =C26/C30 -> 10.729167 | D29: =D26/D30 -> 31.770833 | E29: =E26/E30 -> 48.229167 | F29: =F26/F30 -> 47.604167 | G29: =G26/G30 -> 71.881188 | H29: =H26/H30 -> 59.707242 | I29: =I26/I30 -> 92.340981 | J29: =J26/J30 -> 141.56587 | ... L29: =L26/L30 -> 264.42845
A30: Shares Outstanding (Cr) | C30: 0.96 | D30: 0.96 | E30: 0.96 | F30: 0.96 | G30: 1.01 | H30: 1.0384 | I30: 1.0384 | J30: 1.0384 | K30: 1.0384 | L30: 1.0384

Sheet Balance Sheet
A1: BETA DRUGS LTD — CONSOLIDATED BALANCE SHEET
A2: All figures in ₹ Crores | As at March end
A4: Particulars | C4: FY21A | D4: FY22A | E4: FY23A | F4: FY24A | G4: FY25A | H4: FY26E | I4: FY27E | J4: FY28E | K4: FY29E | L4: FY30E
A5: EQUITY & LIABILITIES
A6: Share Capital | C6: 9.6 | D6: 9.6 | E6: 9.6 | F6: 9.6 | G6: 10.1 | H6: 10.38 | I6: 10.38 | J6: 10.38 | K6: 10.38 | L6: 10.38
A7: Reserves & Surplus | C7: 38.4 | D7: 68.9 | E7: 115.2 | F7: 157.4 | G7: 187.2 | H7: =G7+('Income Statement'!H26*0.85)+48.3 -> 288.2 | I7: =H7+('Income Statement'!I26*0.85) -> 369.70384 | J7: =I7+('Income Statement'!J26*0.85) -> 494.65554 | K7: =J7+('Income Statement'!K26*0.85) -> 670.04114 | L7: =K7+('Income Statement'!L26*0.85) -> 903.43627
A8: Total Equity | C8: =C6+C7 -> 48 | D8: =D6+D7 -> 78.5 | E8: =E6+E7 -> 124.8 | F8: =F6+F7 -> 167 | G8: =G6+G7 -> 197.3 | H8: =H6+H7 -> 298.58 | I8: =I6+I7 -> 380.08384 | J8: =J6+J7 -> 505.03554 | ... L8: =L6+L7 -> 913.81627
A10: Non-Current Liabilities
A11: Long-term Borrowings | C11: 5 | D11: 3.5 | E11: 7 | F11: 6 | G11: 5 | H11: 4 | I11: 3 | J11: 2 | K11: 1 | L11: 0
A12: Other Non-Current Liabilities | C12: 2 | D12: 3.5 | E12: 3.5 | F12: 5 | G12: 120 | H12: 115 | I12: 110 | J12: 105 | K12: 100 | L12: 95
A14: Current Liabilities
A15: Trade Payables | C15: 10.2 | D15: 18 | E15: 20.4 | F15: 29.3 | G15: 35 | H15: ='Income Statement'!H11*Assumptions!G35/365 -> 36.054795 | I15: ='Income Statement'!I11*Assumptions!H35/365 -> 46.198082 | J15: ='Income Statement'!J11*Assumptions!I35/365 -> 56.416438 | K15: ='Income Statement'!K11*Assumptions!J35/365 -> 67.197808 | L15: ='Income Statement'!L11*Assumptions!K35/365 -> 78.706849
A16: Short-term Borrowings | C16: 8 | D16: 5 | E16: 10 | F16: 15 | G16: 12 | H16: 10 | I16: 8 | J16: 6 | K16: 4 | L16: 2
A17: Other Current Liabilities | C17: 23.8 | D17: 43.6 | E17: 36 | F17: 50 | G17: 55 | H17: 50 | I17: 55 | J17: 60 | K17: 65 | L17: 70
A18: Total Current Liabilities | C18: =C15+C16+C17 -> 42 | D18: =D15+D16+D17 -> 66.6 | E18: =E15+E16+E17 -> 66.4 | F18: =F15+F16+F17 -> 94.3 | G18: =G15+G16+G17 -> 102 | H18: =H15+H16+H17 -> 96.054795 | I18: =I15+I16+I17 -> 109.19808 | J18: =J15+J16+J17 -> 122.41644 | ... L18: =L15+L16+L17 -> 150.70685
A20: TOTAL EQUITY & LIABILITIES | C20: =C8+C11+C12+C18 -> 97 | D20: =D8+D11+D12+D18 -> 152.1 | E20: =E8+E11+E12+E18 -> 201.7 | F20: =F8+F11+F12+F18 -> 272.3 | G20: =G8+G11+G12+G18 -> 424.3 | H20: =H8+H11+H12+H18 -> 513.63479 | I20: =I8+I11+I12+I18 -> 602.28193 | J20: =J8+J11+J12+J18 -> 734.45198 | ... L20: =L8+L11+L12+L18 -> 1159.5231
A22: ASSETS
A23: Non-Current Assets
A24: Net Fixed Assets (PPE) | C24: 30 | D24: 36 | E24: 47 | F24: 52 | G24: 65 | H24: =G24+Assumptions!G36-'Income Statement'!H20 -> 88 | I24: =H24+Assumptions!H36-'Income Statement'!I20 -> 114.74 | J24: =I24+Assumptions!I36-'Income Statement'!J20 -> 144.02 | K24: =J24+Assumptions!J36-'Income Statement'!K20 -> 173.02 | L24: =K24+Assumptions!K36-'Income Statement'!L20 -> 201.8
A25: Intangible Assets & CWIP | C25: 5 | D25: 8 | E25: 12 | F25: 15 | G25: 20 | H25: 70 | I25: 30 | J25: 35 | K25: 40 | L25: 45
A26: Other Non-Current Assets | C26: 3 | D26: 4 | E26: 5 | F26: 6 | G26: 8 | H26: 10 | I26: 12 | J26: 14 | K26: 16 | L26: 18
A28: Current Assets
A29: Inventories | C29: 11.4 | D29: 22 | E29: 27.5 | F29: 40.7 | G29: 50.8 | H29: ='Income Statement'!H11*Assumptions!G34/365 -> 51.506849 | I29: ='Income Statement'!I11*Assumptions!H34/365 -> 62.503288 | J29: ='Income Statement'!J11*Assumptions!I34/365 -> 73.775342 | K29: ='Income Statement'!K11*Assumptions!J34/365 -> 86.706849 | L29: ='Income Statement'!L11*Assumptions!K34/365 -> 98.383562
A30: Trade Receivables | C30: 37.5 | D30: 66.6 | E30: 84 | F30: 101.7 | G30: 123.2 | H30: ='Income Statement'!H5*Assumptions!G33/365 -> 129.31507 | I30: ='Income Statement'!I5*Assumptions!H33/365 -> 167.23288 | J30: ='Income Statement'!J5*Assumptions!I33/365 -> 207.12329 | K30: ='Income Statement'!K5*Assumptions!J33/365 -> 252.05479 | L30: ='Income Statement'!L5*Assumptions!K33/365 -> 296.71233
A31: Cash & Cash Equivalents | C31: 3 | D31: 3.5 | E31: 5.3 | F31: 15 | G31: 120 | H31: =H20-H24-H25-H26-H29-H30-H32 -> 139.81288 | I31: =I20-I24-I25-I26-I29-I30-I32 -> 185.80576 | J31: =J20-J24-J25-J26-J29-J30-J32 -> 225.53335 | K31: =K20-K24-K25-K26-K29-K30-K32 -> 309.83731 | L31: =L20-L24-L25-L26-L29-L30-L32 -> 454.62723
A32: Other Current Assets | C32: 7.1 | D32: 12 | E32: 20.9 | F32: 41.9 | G32: 37.3 | H32: 25 | I32: 30 | J32: 35 | K32: 40 | L32: 45
A34: TOTAL ASSETS | C34: =C24+C25+C26+C29+C30+C31+C32 -> 97 | D34: =D24+D25+D26+D29+D30+D31+D32 -> 152.1 | E34: =E24+E25+E26+E29+E30+E31+E32 -> 201.7 | F34: =F24+F25+F26+F29+F30+F31+F32 -> 272.3 | G34: =G24+G25+G26+G29+G30+G31+G32 -> 424.3 | H34: =H24+H25+H26+H29+H30+H31+H32 -> 513.63479 | I34: =I24+I25+I26+I29+I30+I31+I32 -> 602.28193 | J34: =J24+J25+J26+J29+J30+J31+J32 -> 734.45198 | ... L34: =L24+L25+L26+L29+L30+L31+L32 -> 1159.5231
A36: B/S Check | C36: =C20-C34 -> 0 | D36: =D20-D34 -> 0 | E36: =E20-E34 -> 0 | F36: =F20-F34 -> 0 | G36: =G20-G34 -> 0 | H36: =H20-H34 -> 0 | I36: =I20-I34 -> 0 | J36: =J20-J34 -> 0 | ... L36: =L20-L34 -> 0

Sheet Cash Flow
A1: BETA DRUGS LTD — CASH FLOW STATEMENT
A2: All figures in ₹ Crores
A4: Particulars | C4: FY21A | D4: FY22A | E4: FY23A | F4: FY24A | G4: FY25A | H4: FY26E | I4: FY27E | J4: FY28E | K4: FY29E | L4: FY30E
A5: A. CASH FLOW FROM OPERATIONS
A6: Net Profit (PAT) | C6: ='Income Statement'!C26 -> 10.3 | D6: ='Income Statement'!D26 -> 30.5 | E6: ='Income Statement'!E26 -> 46.3 | F6: ='Income Statement'!F26 -> 45.7 | G6: ='Income Statement'!G26 -> 72.6 | H6: ='Income Statement'!H26 -> 62 | I6: ='Income Statement'!I26 -> 95.886875 | J6: ='Income Statement'!J26 -> 147.002 | ... L6: ='Income Statement'!L26 -> 274.5825
A7: (+) Depreciation & Amortization | C7: ='Income Statement'!C20 -> 5.5 | D7: ='Income Statement'!D20 -> 6.4 | E7: ='Income Statement'!E20 -> 8 | F7: ='Income Statement'!F20 -> 8.3 | G7: ='Income Statement'!G20 -> 10 | H7: ='Income Statement'!H20 -> 12 | I7: ='Income Statement'!I20 -> 15.26 | J7: ='Income Statement'!J20 -> 18.72 | ... L7: ='Income Statement'!L20 -> 26.22
A8: (+/-) Working Capital Changes | C8: -5 | D8: -12.6 | E8: -28.2 | F8: -21.3 | G8: -36.4 | H8: =-('Balance Sheet'!H29-'Balance Sheet'!G29)-('Balance Sheet'!H30-'Balance Sheet'!G30)-('Balance Sheet'!H32-'Balance Sheet'!G32)+('Balance Sheet'!H15-'Balance Sheet'!G15)+('Balance Sheet'!H17-'Balance Sheet'!G17) -> 1.5328767 | I8: =-('Balance Sheet'!I29-'Balance Sheet'!H29)-('Balance Sheet'!I30-'Balance Sheet'!H30)-('Balance Sheet'!I32-'Balance Sheet'!H32)+('Balance Sheet'!I15-'Balance Sheet'!H15)+('Balance Sheet'!I17-'Balance Sheet'!H17) -> -38.770959 | J8: =-('Balance Sheet'!J29-'Balance Sheet'!I29)-('Balance Sheet'!J30-'Balance Sheet'!I30)-('Balance Sheet'!J32-'Balance Sheet'!I32)+('Balance Sheet'!J15-'Balance Sheet'!I15)+('Balance Sheet'!J17-'Balance Sheet'!I17) -> -40.94411 | K8: =-('Balance Sheet'!K29-'Balance Sheet'!J29)-('Balance Sheet'!K30-'Balance Sheet'!J30)-('Balance Sheet'!K32-'Balance Sheet'!J32)+('Balance Sheet'!K15-'Balance Sheet'!J15)+('Balance Sheet'!K17-'Balance Sheet'!J17) -> -47.081644 | L8: =-('Balance Sheet'!L29-'Balance Sheet'!K29)-('Balance Sheet'!L30-'Balance Sheet'!K30)-('Balance Sheet'!L32-'Balance Sheet'!K32)+('Balance Sheet'!L15-'Balance Sheet'!K15)+('Balance Sheet'!L17-'Balance Sheet'!K17) -> -44.825205
A9: Cash from Operations (CFO) | C9: =C6+C7+C8 -> 10.8 | D9: =D6+D7+D8 -> 24.3 | E9: =E6+E7+E8 -> 26.1 | F9: =F6+F7+F8 -> 32.7 | G9: =G6+G7+G8 -> 46.2 | H9: =H6+H7+H8 -> 75.532877 | I9: =I6+I7+I8 -> 72.375916 | J9: =J6+J7+J8 -> 124.77789 | ... L9: =L6+L7+L8 -> 255.97729
A11: B. CASH FLOW FROM INVESTING
A12: (-) Capital Expenditure | C12: -8 | D12: -12 | E12: -19 | F12: -14 | G12: -25 | H12: =-Assumptions!G36 -> -35 | I12: =-Assumptions!H36 -> -42 | J12: =-Assumptions!I36 -> -48 | K12: =-Assumptions!J36 -> -52 | L12: =-Assumptions!K36 -> -55
A13: (-) Investments & Others | C13: -2 | D13: -5 | E13: -5 | F13: -5 | G13: -7 | H13: =-('Balance Sheet'!H25-'Balance Sheet'!G25)-('Balance Sheet'!H26-'Balance Sheet'!G26) -> -52 | I13: =-('Balance Sheet'!I25-'Balance Sheet'!H25)-('Balance Sheet'!I26-'Balance Sheet'!H26) -> 38 | J13: =-('Balance Sheet'!J25-'Balance Sheet'!I25)-('Balance Sheet'!J26-'Balance Sheet'!I26) -> -7 | K13: =-('Balance Sheet'!K25-'Balance Sheet'!J25)-('Balance Sheet'!K26-'Balance Sheet'!J26) -> -7 | L13: =-('Balance Sheet'!L25-'Balance Sheet'!K25)-('Balance Sheet'!L26-'Balance Sheet'!K26) -> -7
A14: Cash from Investing (CFI) | C14: =C12+C13 -> -10 | D14: =D12+D13 -> -17 | E14: =E12+E13 -> -24 | F14: =F12+F13 -> -19 | G14: =G12+G13 -> -32 | H14: =H12+H13 -> -87 | I14: =I12+I13 -> -4 | J14: =J12+J13 -> -55 | ... L14: =L12+L13 -> -62
A16: C. CASH FLOW FROM FINANCING
A17: (+/-) Debt (Repayment)/Raised | C17: -3 | D17: -5 | E17: 2 | F17: -1 | G17: 100 | H17: =('Balance Sheet'!H11-'Balance Sheet'!G11)+('Balance Sheet'!H12-'Balance Sheet'!G12)+('Balance Sheet'!H16-'Balance Sheet'!G16) -> -8 | I17: =('Balance Sheet'!I11-'Balance Sheet'!H11)+('Balance Sheet'!I12-'Balance Sheet'!H12)+('Balance Sheet'!I16-'Balance Sheet'!H16) -> -8 | J17: =('Balance Sheet'!J11-'Balance Sheet'!I11)+('Balance Sheet'!J12-'Balance Sheet'!I12)+('Balance Sheet'!J16-'Balance Sheet'!I16) -> -8 | K17: =('Balance Sheet'!K11-'Balance Sheet'!J11)+('Balance Sheet'!K12-'Balance Sheet'!J12)+('Balance Sheet'!K16-'Balance Sheet'!J16) -> -8 | L17: =('Balance Sheet'!L11-'Balance Sheet'!K11)+('Balance Sheet'!L12-'Balance Sheet'!K12)+('Balance Sheet'!L16-'Balance Sheet'!K16) -> -8
A18: (-) Dividends Paid | C18: -1.8 | D18: -1.8 | E18: -2.3 | F18: -3 | G18: -9.2 | H18: =-'Income Statement'!H26*0.15 -> -9.3 | I18: =-'Income Statement'!I26*0.15 -> -14.383031 | J18: =-'Income Statement'!J26*0.15 -> -22.0503 | K18: =-'Income Statement'!K26*0.15 -> -30.9504 | L18: =-'Income Statement'!L26*0.15 -> -41.187375
A19: Cash from Financing (CFF) | C19: =C17+C18 -> -4.8 | D19: =D17+D18 -> -6.8 | E19: =E17+E18 -> -0.3 | F19: =F17+F18 -> -4 | G19: =G17+G18 -> 90.8 | H19: =H17+H18 -> -17.3 | I19: =I17+I18 -> -22.383031 | J19: =J17+J18 -> -30.0503 | ... L19: =L17+L18 -> -49.187375
A21: NET CHANGE IN CASH | C21: =C9+C14+C19 -> -4 | D21: =D9+D14+D19 -> 0.5 | E21: =E9+E14+E19 -> 1.8 | F21: =F9+F14+F19 -> 9.7 | G21: =G9+G14+G19 -> 105 | H21: =H9+H14+H19 -> -28.767123 | I21: =I9+I14+I19 -> 45.992885 | J21: =J9+J14+J19 -> 39.72759 | ... L21: =L9+L14+L19 -> 144.78992
A22: Opening Cash Balance | C22: 7 | D22: ='Balance Sheet'!C31 -> 3 | E22: ='Balance Sheet'!D31 -> 3.5 | F22: ='Balance Sheet'!E31 -> 5.3 | G22: ='Balance Sheet'!F31 -> 15 | H22: ='Balance Sheet'!G31 -> 120 | I22: ='Balance Sheet'!H31 -> 139.81288 | J22: ='Balance Sheet'!I31 -> 185.80576 | K22: ='Balance Sheet'!J31 -> 225.53335 | L22: ='Balance Sheet'!K31 -> 309.83731
A23: Closing Cash Balance | C23: =C21+C22 -> 3 | D23: =D21+D22 -> 3.5 | E23: =E21+E22 -> 5.3 | F23: =F21+F22 -> 15 | G23: =G21+G22 -> 120 | H23: =H21+H22 -> 91.232877 | I23: =I21+I22 -> 185.80576 | J23: =J21+J22 -> 225.53335 | ... L23: =L21+L22 -> 454.62723
A25: FREE CASH FLOW (CFO - Capex) | C25: =C9+C12 -> 2.8 | D25: =D9+D12 -> 12.3 | E25: =E9+E12 -> 7.1 | F25: =F9+F12 -> 18.7 | G25: =G9+G12 -> 21.2 | H25: =H9+H12 -> 40.532877 | I25: =I9+I12 -> 30.375916 | J25: =J9+J12 -> 76.77789 | ... L25: =L9+L12 -> 200.97729
A26: FCF Margin (%) | C26: =C25/'Income Statement'!C5 -> 0.030701754 | D26: =D25/'Income Statement'!D5 -> 0.066847826 | E26: =E25/'Income Statement'!E5 -> 0.03126376 | F26: =F25/'Income Statement'!F5 -> 0.06294177 | G26: =G25/'Income Statement'!G5 -> 0.057483731 | H26: =H25/'Income Statement'!H5 -> 0.10133219 | I26: =I25/'Income Statement'!I5 -> 0.055735626 | J26: =J25/'Income Statement'!J5 -> 0.10663596 | ... L26: =L25/'Income Statement'!L5 -> 0.17629587

Sheet Ratios & Valuation
A1: BETA DRUGS LTD — KEY RATIOS & VALUATION
A2: All figures in ₹ Crores unless stated otherwise
A4: Key Metrics | C4: FY21A | D4: FY22A | E4: FY23A | F4: FY24A | G4: FY25A | H4: FY26E | I4: FY27E | J4: FY28E | K4: FY29E | L4: FY30E
A5: PROFITABILITY RATIOS
A6: Gross Margin (%) | C6: =('Income Statement'!C5-'Income Statement'!C11)/'Income Statement'!C5 -> 0.49013158 | D6: =('Income Statement'!D5-'Income Statement'!D11)/'Income Statement'!D5 -> 0.49021739 | E6: =('Income Statement'!E5-'Income Statement'!E11)/'Income Statement'!E5 -> 0.53500661 | F6: =('Income Statement'!F5-'Income Statement'!F11)/'Income Statement'!F5 -> 0.49983171 | G6: =('Income Statement'!G5-'Income Statement'!G11)/'Income Statement'!G5 -> 0.52006508 | H6: =('Income Statement'!H5-'Income Statement'!H11)/'Income Statement'!H5 -> 0.53 | I6: =('Income Statement'!I5-'Income Statement'!I11)/'Income Statement'!I5 -> 0.545 | J6: =('Income Statement'!J5-'Income Statement'!J11)/'Income Statement'!J5 -> 0.56 | ... L6: =('Income Statement'!L5-'Income Statement'!L11)/'Income Statement'!L5 -> 0.58
A7: EBITDA Margin (%) | C7: ='Income Statement'!C18 -> 0.21052632 | D7: ='Income Statement'!D18 -> 0.2298913 | E7: ='Income Statement'!E18 -> 0.26992514 | F7: ='Income Statement'!F18 -> 0.19993268 | G7: ='Income Statement'!G18 -> 0.23020607 | H7: ='Income Statement'!H18 -> 0.22 | I7: ='Income Statement'!I18 -> 0.245 | J7: ='Income Statement'!J18 -> 0.28 | ... L7: ='Income Statement'!L18 -> 0.325
A8: Net Profit Margin (%) | C8: ='Income Statement'!C27 -> 0.1129386 | D8: ='Income Statement'!D27 -> 0.16576087 | E8: ='Income Statement'!E27 -> 0.20387494 | F8: ='Income Statement'!F27 -> 0.15382026 | G8: ='Income Statement'!G27 -> 0.19685466 | H8: ='Income Statement'!H27 -> 0.155 | I8: ='Income Statement'!I27 -> 0.17593922 | J8: ='Income Statement'!J27 -> 0.20416944 | ... L8: ='Income Statement'!L27 -> 0.24086184
A9: ROE (%) | C9: ='Income Statement'!C26/'Balance Sheet'!C8 -> 0.21458333 | D9: ='Income Statement'!D26/'Balance Sheet'!D8 -> 0.38853503 | E9: ='Income Statement'!E26/'Balance Sheet'!E8 -> 0.37099359 | F9: ='Income Statement'!F26/'Balance Sheet'!F8 -> 0.27365269 | G9: ='Income Statement'!G26/'Balance Sheet'!G8 -> 0.36796756 | H9: ='Income Statement'!H26/'Balance Sheet'!H8 -> 0.20764954 | I9: ='Income Statement'!I26/'Balance Sheet'!I8 -> 0.25227822 | J9: ='Income Statement'!J26/'Balance Sheet'!J8 -> 0.29107258 | ... L9: ='Income Statement'!L26/'Balance Sheet'!L8 -> 0.30047889
A10: ROCE (%) | C10: ='Income Statement'!C22/('Balance Sheet'!C8+'Balance Sheet'!C11+'Balance Sheet'!C16) -> 0.23114754 | D10: ='Income Statement'!D22/('Balance Sheet'!D8+'Balance Sheet'!D11+'Balance Sheet'!D16) -> 0.44942529 | E10: ='Income Statement'!E22/('Balance Sheet'!E8+'Balance Sheet'!E11+'Balance Sheet'!E16) -> 0.38857546 | F10: ='Income Statement'!F22/('Balance Sheet'!F8+'Balance Sheet'!F11+'Balance Sheet'!F16) -> 0.29893617 | G10: ='Income Statement'!G22/('Balance Sheet'!G8+'Balance Sheet'!G11+'Balance Sheet'!G16) -> 0.38684088 | H10: ='Income Statement'!H22/('Balance Sheet'!H8+'Balance Sheet'!H11+'Balance Sheet'!H16) -> 0.25593448 | I10: ='Income Statement'!I22/('Balance Sheet'!I8+'Balance Sheet'!I11+'Balance Sheet'!I16) -> 0.31636439 | J10: ='Income Statement'!J22/('Balance Sheet'!J8+'Balance Sheet'!J11+'Balance Sheet'!J16) -> 0.36972097 | ... L10: ='Income Statement'!L22/('Balance Sheet'!L8+'Balance Sheet'!L11+'Balance Sheet'!L16) -> 0.38686799
A12: PER SHARE METRICS
A13: EPS (₹) | C13: ='Income Statement'!C29 -> 10.729167 | D13: ='Income Statement'!D29 -> 31.770833 | E13: ='Income Statement'!E29 -> 48.229167 | F13: ='Income Statement'!F29 -> 47.604167 | G13: ='Income Statement'!G29 -> 71.881188 | H13: ='Income Statement'!H29 -> 59.707242 | I13: ='Income Statement'!I29 -> 92.340981 | J13: ='Income Statement'!J29 -> 141.56587 | ... L13: ='Income Statement'!L29 -> 264.42845
A14: Book Value / Share (₹) | C14: ='Balance Sheet'!C8/'Income Statement'!C30 -> 50 | D14: ='Balance Sheet'!D8/'Income Statement'!D30 -> 81.770833 | E14: ='Balance Sheet'!E8/'Income Statement'!E30 -> 130 | F14: ='Balance Sheet'!F8/'Income Statement'!F30 -> 173.95833 | G14: ='Balance Sheet'!G8/'Income Statement'!G30 -> 195.34653 | H14: ='Balance Sheet'!H8/'Income Statement'!H30 -> 287.53852 | I14: ='Balance Sheet'!I8/'Income Statement'!I30 -> 366.02835 | J14: ='Balance Sheet'!J8/'Income Statement'!J30 -> 486.35934 | ... L14: ='Balance Sheet'!L8/'Income Statement'!L30 -> 880.02337
A15: EPS Growth (%) | D15: =(D13-C13)/C13 -> 1.961165 | E15: =(E13-D13)/D13 -> 0.51803279 | F15: =(F13-E13)/E13 -> -0.012958963 | G15: =(G13-F13)/F13 -> 0.50997682 | H15: =(H13-G13)/G13 -> -0.16936206 | I15: =(I13-H13)/H13 -> 0.5465625 | J15: =(J13-I13)/I13 -> 0.53307739 | K15: =(K13-J13)/J13 -> 0.40362716 | L15: =(L13-K13)/K13 -> 0.33075421
A17: EFFICIENCY RATIOS
A18: Debtor Days | C18: 150 | D18: 132 | E18: 135 | F18: 125 | G18: 122 | H18: 120 | I18: 115 | J18: 110 | K18: 105 | L18: 100
A19: Inventory Days | C19: 90 | D19: 85 | E19: 95 | F19: 100 | G19: 105 | H19: 100 | I19: 95 | J19: 90 | K19: 85 | L19: 80
A20: Creditor Days | C20: 80 | D20: 70 | E20: 75 | F20: 72 | G20: 70 | H20: 70 | I20: 68 | J20: 65 | K20: 62 | L20: 60
A21: Debt/Equity | C21: =('Balance Sheet'!C11+'Balance Sheet'!C16)/'Balance Sheet'!C8 -> 0.27083333 | D21: =('Balance Sheet'!D11+'Balance Sheet'!D16)/'Balance Sheet'!D8 -> 0.10828025 | E21: =('Balance Sheet'!E11+'Balance Sheet'!E16)/'Balance Sheet'!E8 -> 0.13621795 | F21: =('Balance Sheet'!F11+'Balance Sheet'!F16)/'Balance Sheet'!F8 -> 0.1257485 | G21: =('Balance Sheet'!G11+'Balance Sheet'!G16)/'Balance Sheet'!G8 -> 0.086163203 | H21: =('Balance Sheet'!H11+'Balance Sheet'!H16)/'Balance Sheet'!H8 -> 0.046888606 | I21: =('Balance Sheet'!I11+'Balance Sheet'!I16)/'Balance Sheet'!I8 -> 0.028940983 | J21: =('Balance Sheet'!J11+'Balance Sheet'!J16)/'Balance Sheet'!J8 -> 0.015840469 | ... L21: =('Balance Sheet'!L11+'Balance Sheet'!L16)/'Balance Sheet'!L8 -> 0.0021886238
A22: Current Ratio | C22: =('Balance Sheet'!C29+'Balance Sheet'!C30+'Balance Sheet'!C31+'Balance Sheet'!C32)/'Balance Sheet'!C18 -> 1.4047619 | D22: =('Balance Sheet'!D29+'Balance Sheet'!D30+'Balance Sheet'!D31+'Balance Sheet'!D32)/'Balance Sheet'!D18 -> 1.5630631 | E22: =('Balance Sheet'!E29+'Balance Sheet'!E30+'Balance Sheet'!E31+'Balance Sheet'!E32)/'Balance Sheet'!E18 -> 2.0737952 | F22: =('Balance Sheet'!F29+'Balance Sheet'!F30+'Balance Sheet'!F31+'Balance Sheet'!F32)/'Balance Sheet'!F18 -> 2.1134677 | G22: =('Balance Sheet'!G29+'Balance Sheet'!G30+'Balance Sheet'!G31+'Balance Sheet'!G32)/'Balance Sheet'!G18 -> 3.2480392 | H22: =('Balance Sheet'!H29+'Balance Sheet'!H30+'Balance Sheet'!H31+'Balance Sheet'!H32)/'Balance Sheet'!H18 -> 3.5983086 | I22: =('Balance Sheet'!I29+'Balance Sheet'!I30+'Balance Sheet'!I31+'Balance Sheet'!I32)/'Balance Sheet'!I18 -> 4.0801259 | J22: =('Balance Sheet'!J29+'Balance Sheet'!J30+'Balance Sheet'!J31+'Balance Sheet'!J32)/'Balance Sheet'!J18 -> 4.4228699 | ... L22: =('Balance Sheet'!L29+'Balance Sheet'!L30+'Balance Sheet'!L31+'Balance Sheet'!L32)/'Balance Sheet'!L18 -> 5.9368444
A23: Interest Coverage (x) | C23: =IF('Income Statement'!C21=0,0,'Income Statement'!C17/'Income Statement'!C21) -> 10.666667 | D23: =IF('Income Statement'!D21=0,0,'Income Statement'!D17/'Income Statement'!D21) -> 23.5 | E23: =IF('Income Statement'!E21=0,0,'Income Statement'!E17/'Income Statement'!E21) -> 26.652174 | F23: =IF('Income Statement'!F21=0,0,'Income Statement'!F17/'Income Statement'!F21) -> 19.8 | G23: =IF('Income Statement'!G21=0,0,'Income Statement'!G17/'Income Statement'!G21) -> 9.2282609 | H23: =IF('Income Statement'!H21=0,0,'Income Statement'!H17/'Income Statement'!H21) -> 14.666667 | I23: =IF('Income Statement'!I21=0,0,'Income Statement'!I17/'Income Statement'!I21) -> 20.416667 | J23: =IF('Income Statement'!J21=0,0,'Income Statement'!J17/'Income Statement'!J21) -> 28 | ... L23: =IF('Income Statement'!L21=0,0,'Income Statement'!L17/'Income Statement'!L21) -> 46.428571
A25: GROWTH METRICS
A26: Revenue Growth (%) | C26: ='Income Statement'!C6 -> 0.28 | D26: ='Income Statement'!D6 -> 0.58 | E26: ='Income Statement'!E6 -> 0.234 | F26: ='Income Statement'!F6 -> 0.308 | G26: ='Income Statement'!G6 -> 0.241 | H26: ='Income Statement'!H6 -> 0.084598698 | I26: ='Income Statement'!I6 -> 0.3625 | J26: ='Income Statement'!J6 -> 0.32110092 | ... L26: ='Income Statement'!L6 -> 0.23913043
A27: EBITDA Growth (%) | D27: =('Income Statement'!D17-'Income Statement'!C17)/'Income Statement'!C17 -> 1.203125 | E27: =('Income Statement'!E17-'Income Statement'!D17)/'Income Statement'!D17 -> 0.44917258 | F27: =('Income Statement'!F17-'Income Statement'!E17)/'Income Statement'!E17 -> -0.030995106 | G27: =('Income Statement'!G17-'Income Statement'!F17)/'Income Statement'!F17 -> 0.42929293 | H27: =('Income Statement'!H17-'Income Statement'!G17)/'Income Statement'!G17 -> 0.036513545 | I27: =('Income Statement'!I17-'Income Statement'!H17)/'Income Statement'!H17 -> 0.51732955 | J27: =('Income Statement'!J17-'Income Statement'!I17)/'Income Statement'!I17 -> 0.50982962 | K27: =('Income Statement'!K17-'Income Statement'!J17)/'Income Statement'!J17 -> 0.39186508 | L27: =('Income Statement'!L17-'Income Statement'!K17)/'Income Statement'!K17 -> 0.32038489
A28: PAT Growth (%) | D28: =('Income Statement'!D26-'Income Statement'!C26)/'Income Statement'!C26 -> 1.961165 | E28: =('Income Statement'!E26-'Income Statement'!D26)/'Income Statement'!D26 -> 0.51803279 | F28: =('Income Statement'!F26-'Income Statement'!E26)/'Income Statement'!E26 -> -0.012958963 | G28: =('Income Statement'!G26-'Income Statement'!F26)/'Income Statement'!F26 -> 0.58862144 | H28: =('Income Statement'!H26-'Income Statement'!G26)/'Income Statement'!G26 -> -0.14600551 | I28: =('Income Statement'!I26-'Income Statement'!H26)/'Income Statement'!H26 -> 0.5465625 | J28: =('Income Statement'!J26-'Income Statement'!I26)/'Income Statement'!I26 -> 0.53307739 | K28: =('Income Statement'!K26-'Income Statement'!J26)/'Income Statement'!J26 -> 0.40362716 | L28: =('Income Statement'!L26-'Income Statement'!K26)/'Income Statement'!K26 -> 0.33075421
A30: VALUATION METRICS
A31: CMP (₹) | H31: 1101
A32: Market Cap (₹ Cr) | H32: =H31*Assumptions!G38 -> 1143.2784
A33: P/E Ratio (x) | C33: =IF(C13=0,0,$H$31/C13) -> 102.61748 | D33: =IF(D13=0,0,$H$31/D13) -> 34.654426 | E33: =IF(E13=0,0,$H$31/E13) -> 22.82851 | F33: =IF(F13=0,0,$H$31/F13) -> 23.128228 | G33: =IF(G13=0,0,$H$31/G13) -> 15.316942 | H33: =IF(H13=0,0,$H$31/H13) -> 18.439974 | I33: =IF(I13=0,0,$H$31/I13) -> 11.9232 | J33: =IF(J13=0,0,$H$31/J13) -> 7.7772983 | ... L33: =IF(L13=0,0,$H$31/L13) -> 4.1636972
A34: EV/EBITDA (x) | C34: =($H$32+'Balance Sheet'!C11+'Balance Sheet'!C16-'Balance Sheet'!C31)/'Income Statement'!C17 -> 60.066583 | D34: =($H$32+'Balance Sheet'!D11+'Balance Sheet'!D16-'Balance Sheet'!D31)/'Income Statement'!D17 -> 27.146061 | E34: =($H$32+'Balance Sheet'!E11+'Balance Sheet'!E16-'Balance Sheet'!E31)/'Income Statement'!E17 -> 18.841409 | F34: =($H$32+'Balance Sheet'!F11+'Balance Sheet'!F16-'Balance Sheet'!F31)/'Income Statement'!F17 -> 19.348121 | G34: =($H$32+'Balance Sheet'!G11+'Balance Sheet'!G16-'Balance Sheet'!G31)/'Income Statement'!G17 -> 12.252985 | H34: =($H$32+'Balance Sheet'!H11+'Balance Sheet'!H16-'Balance Sheet'!H31)/'Income Statement'!H17 -> 11.562108 | I34: =($H$32+'Balance Sheet'!I11+'Balance Sheet'!I16-'Balance Sheet'!I31)/'Income Statement'!I17 -> 7.2531184 | J34: =($H$32+'Balance Sheet'!J11+'Balance Sheet'!J16-'Balance Sheet'!J31)/'Income Statement'!J17 -> 4.5919893 | ... L34: =($H$32+'Balance Sheet'!L11+'Balance Sheet'!L16-'Balance Sheet'!L31)/'Income Statement'!L17 -> 1.8641057
A35: P/BV (x) | C35: =IF(C14=0,0,$H$31/C14) -> 22.02 | D35: =IF(D14=0,0,$H$31/D14) -> 13.464459 | E35: =IF(E14=0,0,$H$31/E14) -> 8.4692308 | F35: =IF(F14=0,0,$H$31/F14) -> 6.3291018 | G35: =IF(G14=0,0,$H$31/G14) -> 5.6361379 | H35: =IF(H14=0,0,$H$31/H14) -> 3.8290522 | I35: =IF(I14=0,0,$H$31/I14) -> 3.0079637 | J35: =IF(J14=0,0,$H$31/J14) -> 2.2637583 | ... L35: =IF(L14=0,0,$H$31/L14) -> 1.2511031
A37: REVENUE CAGR
A38: FY21-FY25 Revenue CAGR | G38: =('Income Statement'!G5/'Income Statement'!C5)^(1/4)-1 -> 0.41807441
A39: FY25-FY30E Revenue CAGR | L39: =('Income Statement'!L5/'Income Statement'!G5)^(1/5)-1 -> 0.25320693
A40: FY25-FY30E PAT CAGR | L40: =('Income Statement'!L26/'Income Statement'!G26)^(1/5)-1 -> 0.30480991

Sheet Valuation Exercise
A1: BETA DRUGS LTD — VALUATION ANALYSIS
A2: DCF & Comparable Company Analysis | All figures in ₹ Crores unless stated otherwise
A4: SECTION A: KEY ASSUMPTIONS
A5: Parameter | B5: Value | C5: Notes
A6: WACC (Base Case) | B6: 0.13 | C6: Mid-cap Indian Pharma benchmark
A7: Terminal Growth Rate (g) | B7: 0.05 | C7: Per user specification
A8: Shares Outstanding (Cr) | B8: ='Income Statement'!L30 -> 1.0384 | C8: From Income Statement
A9: Current Net Debt (FY25A) | B9: ='Balance Sheet'!G11+'Balance Sheet'!G16-'Balance Sheet'!G31 -> -103 | C9: LT Borrow + ST Borrow - Cash (FY25A)
A10: Projection Period | B10: FY26E – FY30E (5 Years)
A11: Valuation Date | B11: As of FY25A (Mar 2025)
A12: Discount Method | B12: Mid-Year Convention
A14: SECTION B: DCF VALUATION
B15: FY26E | C15: FY27E | D15: FY28E | E15: FY29E | F15: FY30E
A16: Free Cash Flow (₹ Cr) | B16: ='Cash Flow'!H25 -> 40.532877 | C16: ='Cash Flow'!I25 -> 30.375916 | D16: ='Cash Flow'!J25 -> 76.77789 | E16: ='Cash Flow'!K25 -> 130.25436 | F16: ='Cash Flow'!L25 -> 200.97729
A17: Discount Period (Mid-Year) | B17: 0.5 | C17: 1.5 | D17: 2.5 | E17: 3.5 | F17: 4.5
A18: Discount Factor | B18: =1/(1+$B$6)^B17 -> 0.94072087 | C18: =1/(1+$B$6)^C17 -> 0.83249634 | D18: =1/(1+$B$6)^D17 -> 0.73672243 | E18: =1/(1+$B$6)^E17 -> 0.65196675 | F18: =1/(1+$B$6)^F17 -> 0.57696173
A19: PV of FCF (₹ Cr) | B19: =B16*B18 -> 38.130123 | C19: =C16*C18 -> 25.287839 | D19: =D16*D18 -> 56.563994 | E19: =E16*E18 -> 84.921509 | F19: =F16*F18 -> 115.95621
A21: Sum of PV of FCFs | B21: =SUM(B19:F19) -> 320.85967
A22: Terminal Value (Gordon Growth) | B22: =F16*(1+$B$7)/($B$6-$B$7) -> 2637.827 | C22: FCF(FY30E) x (1+g) / (WACC-g)
A23: PV of Terminal Value | B23: =B22/(1+$B$6)^F17 -> 1521.9252
A25: Enterprise Value (Rs Cr) | B25: =B21+B23 -> 1842.7849 | C25: PV of FCFs + PV of TV
A26: (-) Net Debt (FY25A) | B26: =B9 -> -103 | C26: Neg = Net Cash (adds to equity)
A27: Equity Value (Rs Cr) | B27: =B25-B26 -> 1945.7849
A28: Shares Outstanding (Cr) | B28: =B8 -> 1.0384
A29: DCF Value per Share (Rs) | B29: =B27/B28 -> 1873.8298 | C29: Equity Value / Shares
A30: Current Market Price (Rs) | B30: 1101
A32: SECTION C: DCF SENSITIVITY TABLE (Value per Share in Rs)
A33: WACC \ Terminal Growth | B33: 0.03 | C33: 0.04 | D33: 0.045 | E33: 0.05 | F33: 0.055 | G33: 0.06 | H33: 0.07
A34: 0.11 | B34: =(B$16/(1+$A34)^0.5+C$16/(1+$A34)^1.5+D$16/(1+$A34)^2.5+E$16/(1+$A34)^3.5+F$16/(1+$A34)^4.5+F$16*(1+B$33)/($A34-B$33)/(1+$A34)^4.5-$B$9)/$B$8 -> 1984.3125 | C34: =(B$16/(1+$A34)^0.5+C$16/(1+$A34)^1.5+D$16/(1+$A34)^2.5+E$16/(1+$A34)^3.5+F$16/(1+$A34)^4.5+F$16*(1+C$33)/($A34-C$33)/(1+$A34)^4.5-$B$9)/$B$8 -> 2224.1759 | D34: =(B$16/(1+$A34)^0.5+C$16/(1+$A34)^1.5+D$16/(1+$A34)^2.5+E$16/(1+$A34)^3.5+F$16/(1+$A34)^4.5+F$16*(1+D$33)/($A34-D$33)/(1+$A34)^4.5-$B$9)/$B$8 -> 2371.7841 | E34: =(B$16/(1+$A34)^0.5+C$16/(1+$A34)^1.5+D$16/(1+$A34)^2.5+E$16/(1+$A34)^3.5+F$16/(1+$A34)^4.5+F$16*(1+E$33)/($A34-E$33)/(1+$A34)^4.5-$B$9)/$B$8 -> 2543.9937 | F34: =(B$16/(1+$A34)^0.5+C$16/(1+$A34)^1.5+D$16/(1+$A34)^2.5+E$16/(1+$A34)^3.5+F$16/(1+$A34)^4.5+F$16*(1+F$33)/($A34-F$33)/(1+$A34)^4.5-$B$9)/$B$8 -> 2747.5141 | G34: =(B$16/(1+$A34)^0.5+C$16/(1+$A34)^1.5+D$16/(1+$A34)^2.5+E$16/(1+$A34)^3.5+F$16/(1+$A34)^4.5+F$16*(1+G$33)/($A34-G$33)/(1+$A34)^4.5-$B$9)/$B$8 -> 2991.7385 | H34: =(B$16/(1+$A34)^0.5+C$16/(1+$A34)^1.5+D$16/(1+$A34)^2.5+E$16/(1+$A34)^3.5+F$16/(1+$A34)^4.5+F$16*(1+H$33)/($A34-H$33)/(1+$A34)^4.5-$B$9)/$B$8 -> 3663.3559
A35: 0.115 | B35: =(B$16/(1+$A35)^0.5+C$16/(1+$A35)^1.5+D$16/(1+$A35)^2.5+E$16/(1+$A35)^3.5+F$16/(1+$A35)^4.5+F$16*(1+B$33)/($A35-B$33)/(1+$A35)^4.5-$B$9)/$B$8 -> 1858.6351 | C35: =(B$16/(1+$A35)^0.5+C$16/(1+$A35)^1.5+D$16/(1+$A35)^2.5+E$16/(1+$A35)^3.5+F$16/(1+$A35)^4.5+F$16*(1+C$33)/($A35-C$33)/(1+$A35)^4.5-$B$9)/$B$8 -> 2066.0501 | D35: =(B$16/(1+$A35)^0.5+C$16/(1+$A35)^1.5+D$16/(1+$A35)^2.5+E$16/(1+$A35)^3.5+F$16/(1+$A35)^4.5+F$16*(1+D$33)/($A35-D$33)/(1+$A35)^4.5-$B$9)/$B$8 -> 2191.9806 | E35: =(B$16/(1+$A35)^0.5+C$16/(1+$A35)^1.5+D$16/(1+$A35)^2.5+E$16/(1+$A35)^3.5+F$16/(1+$A35)^4.5+F$16*(1+E$33)/($A35-E$33)/(1+$A35)^4.5-$B$9)/$B$8 -> 2337.285 | F35: =(B$16/(1+$A35)^0.5+C$16/(1+$A35)^1.5+D$16/(1+$A35)^2.5+E$16/(1+$A35)^3.5+F$16/(1+$A35)^4.5+F$16*(1+F$33)/($A35-F$33)/(1+$A35)^4.5-$B$9)/$B$8 -> 2506.8069 | G35: =(B$16/(1+$A35)^0.5+C$16/(1+$A35)^1.5+D$16/(1+$A35)^2.5+E$16/(1+$A35)^3.5+F$16/(1+$A35)^4.5+F$16*(1+G$33)/($A35-G$33)/(1+$A35)^4.5-$B$9)/$B$8 -> 2707.1509 | H35: =(B$16/(1+$A35)^0.5+C$16/(1+$A35)^1.5+D$16/(1+$A35)^2.5+E$16/(1+$A35)^3.5+F$16/(1+$A35)^4.5+F$16*(1+H$33)/($A35-H$33)/(1+$A35)^4.5-$B$9)/$B$8 -> 3241.4016
A36: 0.12 | B36: =(B$16/(1+$A36)^0.5+C$16/(1+$A36)^1.5+D$16/(1+$A36)^2.5+E$16/(1+$A36)^3.5+F$16/(1+$A36)^4.5+F$16*(1+B$33)/($A36-B$33)/(1+$A36)^4.5-$B$9)/$B$8 -> 1747.1771 | C36: =(B$16/(1+$A36)^0.5+C$16/(1+$A36)^1.5+D$16/(1+$A36)^2.5+E$16/(1+$A36)^3.5+F$16/(1+$A36)^4.5+F$16*(1+C$33)/($A36-C$33)/(1+$A36)^4.5-$B$9)/$B$8 -> 1927.9722 | D36: =(B$16/(1+$A36)^0.5+C$16/(1+$A36)^1.5+D$16/(1+$A36)^2.5+E$16/(1+$A36)^3.5+F$16/(1+$A36)^4.5+F$16*(1+D$33)/($A36-D$33)/(1+$A36)^4.5-$B$9)/$B$8 -> 2036.4493 | E36: =(B$16/(1+$A36)^0.5+C$16/(1+$A36)^1.5+D$16/(1+$A36)^2.5+E$16/(1+$A36)^3.5+F$16/(1+$A36)^4.5+F$16*(1+E$33)/($A36-E$33)/(1+$A36)^4.5-$B$9)/$B$8 -> 2160.4231 | F36: =(B$16/(1+$A36)^0.5+C$16/(1+$A36)^1.5+D$16/(1+$A36)^2.5+E$16/(1+$A36)^3.5+F$16/(1+$A36)^4.5+F$16*(1+F$33)/($A36-F$33)/(1+$A36)^4.5-$B$9)/$B$8 -> 2303.4698 | G36: =(B$16/(1+$A36)^0.5+C$16/(1+$A36)^1.5+D$16/(1+$A36)^2.5+E$16/(1+$A36)^3.5+F$16/(1+$A36)^4.5+F$16*(1+G$33)/($A36-G$33)/(1+$A36)^4.5-$B$9)/$B$8 -> 2470.3576 | H36: =(B$16/(1+$A36)^0.5+C$16/(1+$A36)^1.5+D$16/(1+$A36)^2.5+E$16/(1+$A36)^3.5+F$16/(1+$A36)^4.5+F$16*(1+H$33)/($A36-H$33)/(1+$A36)^4.5-$B$9)/$B$8 -> 2904.266
A37: 0.13 | B37: =(B$16/(1+$A37)^0.5+C$16/(1+$A37)^1.5+D$16/(1+$A37)^2.5+E$16/(1+$A37)^3.5+F$16/(1+$A37)^4.5+F$16*(1+B$33)/($A37-B$33)/(1+$A37)^4.5-$B$9)/$B$8 -> 1558.3673 | C37: =(B$16/(1+$A37)^0.5+C$16/(1+$A37)^1.5+D$16/(1+$A37)^2.5+E$16/(1+$A37)^3.5+F$16/(1+$A37)^4.5+F$16*(1+C$33)/($A37-C$33)/(1+$A37)^4.5-$B$9)/$B$8 -> 1698.5729 | D37: =(B$16/(1+$A37)^0.5+C$16/(1+$A37)^1.5+D$16/(1+$A37)^2.5+E$16/(1+$A37)^3.5+F$16/(1+$A37)^4.5+F$16*(1+D$33)/($A37-D$33)/(1+$A37)^4.5-$B$9)/$B$8 -> 1781.0467 | E37: =(B$16/(1+$A37)^0.5+C$16/(1+$A37)^1.5+D$16/(1+$A37)^2.5+E$16/(1+$A37)^3.5+F$16/(1+$A37)^4.5+F$16*(1+E$33)/($A37-E$33)/(1+$A37)^4.5-$B$9)/$B$8 -> 1873.8298 | F37: =(B$16/(1+$A37)^0.5+C$16/(1+$A37)^1.5+D$16/(1+$A37)^2.5+E$16/(1+$A37)^3.5+F$16/(1+$A37)^4.5+F$16*(1+F$33)/($A37-F$33)/(1+$A37)^4.5-$B$9)/$B$8 -> 1978.984 | G37: =(B$16/(1+$A37)^0.5+C$16/(1+$A37)^1.5+D$16/(1+$A37)^2.5+E$16/(1+$A37)^3.5+F$16/(1+$A37)^4.5+F$16*(1+G$33)/($A37-G$33)/(1+$A37)^4.5-$B$9)/$B$8 -> 2099.1602 | H37: =(B$16/(1+$A37)^0.5+C$16/(1+$A37)^1.5+D$16/(1+$A37)^2.5+E$16/(1+$A37)^3.5+F$16/(1+$A37)^4.5+F$16*(1+H$33)/($A37-H$33)/(1+$A37)^4.5-$B$9)/$B$8 -> 2399.6007
A38: 0.14 | B38: =(B$16/(1+$A38)^0.5+C$16/(1+$A38)^1.5+D$16/(1+$A38)^2.5+E$16/(1+$A38)^3.5+F$16/(1+$A38)^4.5+F$16*(1+B$33)/($A38-B$33)/(1+$A38)^4.5-$B$9)/$B$8 -> 1404.6678 | C38: =(B$16/(1+$A38)^0.5+C$16/(1+$A38)^1.5+D$16/(1+$A38)^2.5+E$16/(1+$A38)^3.5+F$16/(1+$A38)^4.5+F$16*(1+C$33)/($A38-C$33)/(1+$A38)^4.5-$B$9)/$B$8 -> 1515.8979 | D38: =(B$16/(1+$A38)^0.5+C$16/(1+$A38)^1.5+D$16/(1+$A38)^2.5+E$16/(1+$A38)^3.5+F$16/(1+$A38)^4.5+F$16*(1+D$33)/($A38-D$33)/(1+$A38)^4.5-$B$9)/$B$8 -> 1580.2944 | E38: =(B$16/(1+$A38)^0.5+C$16/(1+$A38)^1.5+D$16/(1+$A38)^2.5+E$16/(1+$A38)^3.5+F$16/(1+$A38)^4.5+F$16*(1+E$33)/($A38-E$33)/(1+$A38)^4.5-$B$9)/$B$8 -> 1651.846 | F38: =(B$16/(1+$A38)^0.5+C$16/(1+$A38)^1.5+D$16/(1+$A38)^2.5+E$16/(1+$A38)^3.5+F$16/(1+$A38)^4.5+F$16*(1+F$33)/($A38-F$33)/(1+$A38)^4.5-$B$9)/$B$8 -> 1731.8154 | G38: =(B$16/(1+$A38)^0.5+C$16/(1+$A38)^1.5+D$16/(1+$A38)^2.5+E$16/(1+$A38)^3.5+F$16/(1+$A38)^4.5+F$16*(1+G$33)/($A38-G$33)/(1+$A38)^4.5-$B$9)/$B$8 -> 1821.781 | H38: =(B$16/(1+$A38)^0.5+C$16/(1+$A38)^1.5+D$16/(1+$A38)^2.5+E$16/(1+$A38)^3.5+F$16/(1+$A38)^4.5+F$16*(1+H$33)/($A38-H$33)/(1+$A38)^4.5-$B$9)/$B$8 -> 2040.2688
A39: 0.15 | B39: =(B$16/(1+$A39)^0.5+C$16/(1+$A39)^1.5+D$16/(1+$A39)^2.5+E$16/(1+$A39)^3.5+F$16/(1+$A39)^4.5+F$16*(1+B$33)/($A39-B$33)/(1+$A39)^4.5-$B$9)/$B$8 -> 1277.27 | C39: =(B$16/(1+$A39)^0.5+C$16/(1+$A39)^1.5+D$16/(1+$A39)^2.5+E$16/(1+$A39)^3.5+F$16/(1+$A39)^4.5+F$16*(1+C$33)/($A39-C$33)/(1+$A39)^4.5-$B$9)/$B$8 -> 1367.1713 | D39: =(B$16/(1+$A39)^0.5+C$16/(1+$A39)^1.5+D$16/(1+$A39)^2.5+E$16/(1+$A39)^3.5+F$16/(1+$A39)^4.5+F$16*(1+D$33)/($A39-D$33)/(1+$A39)^4.5-$B$9)/$B$8 -> 1418.5434 | E39: =(B$16/(1+$A39)^0.5+C$16/(1+$A39)^1.5+D$16/(1+$A39)^2.5+E$16/(1+$A39)^3.5+F$16/(1+$A39)^4.5+F$16*(1+E$33)/($A39-E$33)/(1+$A39)^4.5-$B$9)/$B$8 -> 1475.0528 | F39: =(B$16/(1+$A39)^0.5+C$16/(1+$A39)^1.5+D$16/(1+$A39)^2.5+E$16/(1+$A39)^3.5+F$16/(1+$A39)^4.5+F$16*(1+F$33)/($A39-F$33)/(1+$A39)^4.5-$B$9)/$B$8 -> 1537.5105 | G39: =(B$16/(1+$A39)^0.5+C$16/(1+$A39)^1.5+D$16/(1+$A39)^2.5+E$16/(1+$A39)^3.5+F$16/(1+$A39)^4.5+F$16*(1+G$33)/($A39-G$33)/(1+$A39)^4.5-$B$9)/$B$8 -> 1606.908 | H39: =(B$16/(1+$A39)^0.5+C$16/(1+$A39)^1.5+D$16/(1+$A39)^2.5+E$16/(1+$A39)^3.5+F$16/(1+$A39)^4.5+F$16*(1+H$33)/($A39-H$33)/(1+$A39)^4.5-$B$9)/$B$8 -> 1771.7271
A40: 0.16 | B40: =(B$16/(1+$A40)^0.5+C$16/(1+$A40)^1.5+D$16/(1+$A40)^2.5+E$16/(1+$A40)^3.5+F$16/(1+$A40)^4.5+F$16*(1+B$33)/($A40-B$33)/(1+$A40)^4.5-$B$9)/$B$8 -> 1170.0771 | C40: =(B$16/(1+$A40)^0.5+C$16/(1+$A40)^1.5+D$16/(1+$A40)^2.5+E$16/(1+$A40)^3.5+F$16/(1+$A40)^4.5+F$16*(1+C$33)/($A40-C$33)/(1+$A40)^4.5-$B$9)/$B$8 -> 1243.8769 | D40: =(B$16/(1+$A40)^0.5+C$16/(1+$A40)^1.5+D$16/(1+$A40)^2.5+E$16/(1+$A40)^3.5+F$16/(1+$A40)^4.5+F$16*(1+D$33)/($A40-D$33)/(1+$A40)^4.5-$B$9)/$B$8 -> 1285.5898 | E40: =(B$16/(1+$A40)^0.5+C$16/(1+$A40)^1.5+D$16/(1+$A40)^2.5+E$16/(1+$A40)^3.5+F$16/(1+$A40)^4.5+F$16*(1+E$33)/($A40-E$33)/(1+$A40)^4.5-$B$9)/$B$8 -> 1331.0947 | F40: =(B$16/(1+$A40)^0.5+C$16/(1+$A40)^1.5+D$16/(1+$A40)^2.5+E$16/(1+$A40)^3.5+F$16/(1+$A40)^4.5+F$16*(1+F$33)/($A40-F$33)/(1+$A40)^4.5-$B$9)/$B$8 -> 1380.9335 | G40: =(B$16/(1+$A40)^0.5+C$16/(1+$A40)^1.5+D$16/(1+$A40)^2.5+E$16/(1+$A40)^3.5+F$16/(1+$A40)^4.5+F$16*(1+G$33)/($A40-G$33)/(1+$A40)^4.5-$B$9)/$B$8 -> 1435.7562 | H40: =(B$16/(1+$A40)^0.5+C$16/(1+$A40)^1.5+D$16/(1+$A40)^2.5+E$16/(1+$A40)^3.5+F$16/(1+$A40)^4.5+F$16*(1+H$33)/($A40-H$33)/(1+$A40)^4.5-$B$9)/$B$8 -> 1563.6757
A42: SECTION D: COMPARABLE COMPANY ANALYSIS
A43: Company | B43: Mkt Cap (Rs Cr) | C43: Revenue (Rs Cr) | D43: P/E (TTM) | E43: EV/EBITDA | F43: EV/Revenue | G43: P/Sales
A44: Natco Pharma | B44: 15823 | C44: 4560 | D44: 9 | E44: 8 | F44: 3.5 | G44: 3.5
A45: Alkem Laboratories | B45: 63805 | C45: 14000 | D45: 28.6 | E45: 24.2 | F45: 4.6 | G45: 4.6
A46: Ajanta Pharma | B46: 36482 | C46: 5202 | D46: 35 | E46: 28 | F46: 7 | G46: 7
...
