Workbook

Sheet Assumptions
A1: EMERALD FINANCE LTD - KEY ASSUMPTIONS & DRIVERS
A2: All figures in ₹ Crores unless stated otherwise | Consolidated Basis
A4: HISTORICAL FINANCIALS (Consolidated) | C4: FY23 | D4: FY24 | E4: FY25 | F4: FY26E | G4: FY27E | H4: FY28E | I4: FY29E | J4: FY30E | K4: FY31E | L4: FY32E | M4: FY33E | N4: FY34E | O4: FY35E
A5: Total Income (₹ Cr) | B5: Actual/Est | C5: 11.55 | D5: 13.36 | E5: 21.63 | F5: ='Income Statement'!G6 -> 34.24 | G5: ='Income Statement'!H6 -> 56.5146 | H5: ='Income Statement'!I6 -> 75.05375 | I5: ='Income Statement'!J6 -> 94.30125 | J5: ='Income Statement'!K6 -> 113.27307 | K5: ='Income Statement'!L6 -> 132.34059 | L5: ='Income Statement'!M6 -> 158.24187 | M5: ='Income Statement'!N6 -> 189.84326 | ... O5: ='Income Statement'!P6 -> 250.60566
A6: YoY Growth (%) | D6: =(D5-C5)/C5 -> 0.15670996 | E6: =(E5-D5)/E5 -> 0.38233934 | F6: =(F5-E5)/E5 -> 0.58298659 | G6: =(G5-F5)/F5 -> 0.65054322 | H6: =(H5-G5)/G5 -> 0.32804178 | I6: =(I5-H5)/H5 -> 0.25644954 | J6: =(J5-I5)/I5 -> 0.20118318 | K6: =(K5-J5)/J5 -> 0.16833226 | L6: =(L5-K5)/K5 -> 0.19571681 | M6: =(M5-L5)/L5 -> 0.19970314 | ... O6: =(O5-N5)/N5 -> 0.14283962
A7: Net Profit (₹ Cr) | C7: 3.45 | D7: 4.14 | E7: 10.81 | F7: ='Income Statement'!G19 -> 17.56 | G7: ='Income Statement'!H19 -> 32.1646 | H7: ='Income Statement'!I19 -> 42.19375 | I7: ='Income Statement'!J19 -> 52.24125 | J7: ='Income Statement'!K19 -> 61.643075 | K7: ='Income Statement'!L19 -> 70.990588 | L7: ='Income Statement'!M19 -> 84.071866 | M7: ='Income Statement'!N19 -> 100.22326 | ... O7: ='Income Statement'!P19 -> 129.31566
A8: PAT Growth (%) | D8: =(D7-C7)/C7 -> 0.2 | E8: =(E7-D7)/D7 -> 1.6111111 | F8: =(F7-E7)/E7 -> 0.62442183 | G8: =(G7-F7)/F7 -> 0.83169704 | H8: =(H7-G7)/G7 -> 0.31180708 | I8: =(I7-H7)/H7 -> 0.23812768 | J8: =(J7-I7)/I7 -> 0.17996937 | K8: =(K7-J7)/J7 -> 0.15163931 | ... O8: =(O7-N7)/N7 -> 0.1302501
A10: REVENUE ASSUMPTIONS & DRIVERS
A11: Revenue from Operations (₹ Cr) | C11: 11.51 | D11: 13.32 | E11: 21.57 | F11: ='Income Statement'!G4 -> 34.2 | G11: ='Income Statement'!H4 -> 56.4646 | H11: ='Income Statement'!I4 -> 74.99375 | I11: ='Income Statement'!J4 -> 94.22125 | J11: ='Income Statement'!K4 -> 113.17307 | K11: ='Income Statement'!L4 -> 132.22059 | L11: ='Income Statement'!M4 -> 158.09187 | M11: ='Income Statement'!N4 -> 189.66326 | ... O11: ='Income Statement'!P4 -> 250.35566
A12: Revenue Growth (%) | B12: Assumed | D12: =(D11-C11)/C11 -> 0.15725456 | E12: =(E11-D11)/D11 -> 0.61936937 | F12: 0.45 | G12: 0.745 | H12: 0.334 | I12: 0.275 | J12: 0.197 | K12: 0.192 | L12: 0.178 | M12: 0.155 | N12: 0.137 | O12: 0.123
A14: EWA SEGMENT (Customer Acquisition Channel)
A15: Growth rate in number of employees using EWA per corporate | B15: 0.05
A16: Growth rate of the average amount withdrawn | B16: 0.07
A17: Corporates Onboarded (Cumulative) | B17: # | C17: 15 | D17: 60 | E17: 80 | F17: 210 | G17: 300 | H17: 450 | I17: 600 | J17: 750 | K17: 850 | L17: 1050 | M17: 1350 | N17: 1700 | O17: 2000
A18: Number of Employees who take EWA/corporate onboarded | F18: =ROUND((F19*10000000)/25000/F17,0) -> 23 | G18: =ROUND(F18*(1+$B$15),0) -> 24 | H18: =ROUND(G18*(1+$B$15),0) -> 25 | I18: =ROUND(H18*(1+$B$15),0) -> 26 | J18: =ROUND(I18*(1+$B$15),0) -> 27 | K18: =ROUND(J18*(1+$B$15),0) -> 28 | L18: =ROUND(K18*(1+$B$15),0) -> 29 | M18: =ROUND(L18*(1+$B$15),0) -> 30 | N18: =ROUND(M18*(1+$B$15),0) -> 32 | O18: =ROUND(N18*(1+$B$15),0) -> 34
A19: Monthly EWA Disbursements (₹ Cr) | B19: ₹ Cr/month | C19: 0.5 | D19: 2 | E19: 5 | F19: 12 | G19: =G18*G17*25000*(1+$B$16)*(10^(-7)) -> 19.26 | H19: =H18*H17*25000*(1+$B$16)*(10^(-7)) -> 30.09375 | I19: =I18*I17*25000*(1+$B$16)*(10^(-7)) -> 41.73 | J19: =J18*J17*25000*(1+$B$16)*(10^(-7)) -> 54.16875 | K19: =K18*K17*25000*(1+$B$16)*(10^(-7)) -> 63.665 | L19: =L18*L17*25000*(1+$B$16)*(10^(-7)) -> 81.45375 | M19: =M18*M17*25000*(1+$B$16)*(10^(-7)) -> 108.3375 | N19: =N18*N17*25000*(1+$B$16)*(10^(-7)) -> 145.52 | O19: =O18*O17*25000*(1+$B$16)*(10^(-7)) -> 181.9
A20: EWA IRR / Yield (%) | C20: 0.22 | D20: 0.22 | E20: 0.22 | F20: 0.21 | G20: 0.21 | H20: 0.2 | I20: 0.2 | J20: 0.19 | K20: 0.185 | L20: 0.18 | M20: 0.175 | N20: 0.17 | O20: 0.17
A21: EWA Revenue Contribution (₹ Cr) through processing fees | B21: ₹ Cr | F21: =(F19*12)*(F20/12) -> 2.52 | G21: =(G19*12)*(G20/12) -> 4.0446 | H21: =(H19*12)*(H20/12) -> 6.01875 | I21: =(I19*12)*(I20/12) -> 8.346 | J21: =(J19*12)*(J20/12) -> 10.292063 | K21: =(K19*12)*(K20/12) -> 11.778025 | L21: =(L19*12)*(L20/12) -> 14.661675 | M21: =(M19*12)*(M20/12) -> 18.959062 | ... O21: =(O19*12)*(O20/12) -> 30.923
A22: CROSS-SELL & LENDING (Primary Value Driver)
A23: Rate of growth of Processing Fees from segments other than EWA | B23: 0.05
A24: Processing Fees from segments other than EWA (FY26E) | B24: 2 | F24: =B24 -> 2 | G24: =F24*(1+$B$23) -> 2.1 | H24: =G24*(1+$B$23) -> 2.205 | I24: =H24*(1+$B$23) -> 2.31525 | J24: =I24*(1+$B$23) -> 2.4310125 | K24: =J24*(1+$B$23) -> 2.5525631 | L24: =K24*(1+$B$23) -> 2.6801913 | M24: =L24*(1+$B$23) -> 2.8142008 | N24: =M24*(1+$B$23) -> 2.9549109 | O24: =N24*(1+$B$23) -> 3.1026564
A25: Cross-Sell Quarterly Disbursement (₹ Cr) | B25: ₹ Cr/qtr | C25: 0 | D25: 0 | E25: 15 | F25: 70 | G25: 110 | H25: 150 | I25: 200 | J25: 250 | K25: 290 | L25: 325 | M25: 355 | N25: 380 | O25: 400
A26: Gold Loan Quarterly Disbursement (₹ Cr) | B26: ₹ Cr/qtr | C26: 0 | D26: 50 | E26: 90 | F26: 194 | G26: 500 | H26: 650 | I26: 800 | J26: 900 | K26: 975 | L26: 1070 | M26: 1270 | N26: 1350 | O26: 1400
A27: Syndication Fee (%) | C27: 0 | D27: 0.015 | E27: 0.015 | F27: 0.0125 | G27: 0.012 | H27: 0.012 | I27: 0.0115 | J27: 0.0115 | K27: 0.011 | L27: 0.011 | M27: 0.0105 | N27: 0.01 | O27: 0.01
A28: REVENUE SEGMENT BREAKDOWN | C28: FY23 | D28: FY24 | E28: FY25
A29: A. FEE-BASED INCOME
A30: (i) DSA / Gold Loan Syndication Fees | C30: 5.91 | D30: 5.92 | E30: 8.4 | F30: =ROUND(F26*4*F27+4,2) -> 13.7 | G30: =ROUND(G26*4*G27+4.5,2) -> 28.5 | H30: =ROUND(H26*4*H27+5,2) -> 36.2 | I30: =ROUND(I26*4*I27+5.5,2) -> 42.3 | J30: =ROUND(J26*4*J27+6,2) -> 47.4 | K30: =ROUND(K26*4*K27+6.5,2) -> 49.4 | L30: =ROUND(L26*4*L27+7,2) -> 54.08 | M30: =ROUND(M26*4*M27+7.5,2) -> 60.84 | N30: =ROUND(N26*4*N27+8,2) -> 62 | O30: =ROUND(O26*4*O27+8.5,2) -> 64.5
A31: (ii) Processing Fees (EWA + BL + Cross-sell) | C31: 1 | D31: 1.5 | E31: 2.82 | F31: =F21+F24 -> 4.52 | G31: =G21+G24 -> 6.1446 | H31: =H21+H24 -> 8.22375 | I31: =I21+I24 -> 10.66125 | J31: =J21+J24 -> 12.723075 | K31: =K21+K24 -> 14.330588 | L31: =L21+L24 -> 17.341866 | M31: =M21+M24 -> 21.773263 | ... O31: =O21+O24 -> 34.025656
A32: Total Fee Income (₹ Cr) | C32: =C30+C31 -> 6.91 | D32: =D30+D31 -> 7.42 | E32: =E30+E31 -> 11.22 | F32: =F30+F31 -> 18.22 | G32: =G30+G31 -> 34.6446 | H32: =H30+H31 -> 44.42375 | I32: =I30+I31 -> 52.96125 | J32: =J30+J31 -> 60.123075 | ... O32: =O30+O31 -> 98.525656
A33: Fee Income (% of Revenue) | C33: =C32/C11 -> 0.60034752 | D33: =D32/D11 -> 0.55705706 | E33: =E32/E11 -> 0.5201669 | F33: =F32/F11 -> 0.53274854 | G33: =G32/G11 -> 0.61356319 | H33: =H32/H11 -> 0.59236603 | I33: =I32/I11 -> 0.56209454 | J33: =J32/J11 -> 0.53124893 | ... O33: =O32/O11 -> 0.39354276
A35: B. INTEREST-BASED INCOME
A36: (i) Business/MSME Loan Interest | C36: 4.6 | D36: 5.9 | E36: 10.35 | F36: 11.98 | G36: 12.22 | H36: 15.07 | I36: 18.78 | J36: 24.55 | K36: 33.99 | L36: 47.67 | M36: 65 | N36: 83.72 | O36: 104.93
A37: (ii) EWA Interest Income [ZERO] | C37: 0 | D37: 0 | E37: 0 | F37: 0 | G37: 0 | H37: 0 | I37: 0 | J37: 0 | K37: 0 | L37: 0 | M37: 0 | N37: 0 | O37: 0
A38: (iii) Cross-Sell Loan Interest (Personal Loan etc.) | C38: 0 | D38: 0 | E38: 0 | F38: 4 | G38: 9.6 | H38: 15.5 | I38: 22.48 | J38: 28.5 | K38: 34.5 | L38: 39 | M38: 42.05 | N38: 45.67 | O38: 46.9
A39: Total Interest Income (₹ Cr) | C39: =C36+C37+C38 -> 4.6 | D39: =D36+D37+D38 -> 5.9 | E39: =E36+E37+E38 -> 10.35 | F39: =F36+F37+F38 -> 15.98 | G39: =G36+G37+G38 -> 21.82 | H39: =H36+H37+H38 -> 30.57 | I39: =I36+I37+I38 -> 41.26 | J39: =J36+J37+J38 -> 53.05 | ... O39: =O36+O37+O38 -> 151.83
A40: Interest Income (% of Revenue) | C40: =C39/C11 -> 0.39965248 | D40: =D39/D11 -> 0.44294294 | E40: =E39/E11 -> 0.4798331 | F40: =F39/F11 -> 0.46725146 | G40: =G39/G11 -> 0.38643681 | H40: =H39/H11 -> 0.40763397 | I40: =I39/I11 -> 0.43790546 | J40: =J39/J11 -> 0.46875107 | ... O40: =O39/O11 -> 0.60645724
A42: TOTAL REVENUE (₹ Cr) = Fee + Interest | C42: =C32+C39 -> 11.51 | D42: =D32+D39 -> 13.32 | E42: =E32+E39 -> 21.57 | F42: =F32+F39 -> 34.2 | G42: =G32+G39 -> 56.4646 | H42: =H32+H39 -> 74.99375 | I42: =I32+I39 -> 94.22125 | J42: =J32+J39 -> 113.17307 | ... O42: =O32+O39 -> 250.35566
A43: Revenue Check (should be 0) | C43: =ROUND(C42-C11,2) -> 0 | D43: =ROUND(D42-D11,2) -> 0 | E43: =ROUND(E42-E11,2) -> 0 | F43: =ROUND(F42-F11,2) -> 0 | G43: =ROUND(G42-G11,2) -> 0 | H43: =ROUND(H42-H11,2) -> 0 | I43: =ROUND(I42-I11,2) -> 0 | J43: =ROUND(J42-J11,2) -> 0 | ... O43: =ROUND(O42-O11,2) -> 0
A46: PROFITABILITY ASSUMPTIONS
A47: Employee Cost (% of Revenue) | C47: ='Income Statement'!C9/'Income Statement'!C6 -> 0.13043478 | D47: ='Income Statement'!D9/'Income Statement'!D6 -> 0.093506494 | E47: ='Income Statement'!E9/'Income Statement'!E6 -> 0.15568862 | F47: 0.165 | G47: 0.13 | H47: 0.125 | I47: 0.12 | J47: 0.115 | K47: 0.11 | L47: 0.11 | M47: 0.11 | N47: 0.11 | O47: 0.11
...

Sheet Income Statement
A1: EMERALD FINANCE LTD - CONSOLIDATED INCOME STATEMENT
A2: (₹ Crores)
A3: Particulars | C3: FY22 | D3: FY23 | E3: FY24 | F3: FY25 | G3: FY26E | H3: FY27E | I3: FY28E | J3: FY29E | K3: FY30E | L3: FY31E | M3: FY32E | N3: FY33E | O3: FY34E | P3: FY35E
A4: Revenue from Operations | C4: 8.46 | D4: 11.51 | E4: 13.32 | F4: 21.57 | G4: =Assumptions!F42 -> 34.2 | H4: =Assumptions!G42 -> 56.4646 | I4: =Assumptions!H42 -> 74.99375 | J4: =Assumptions!I42 -> 94.22125 | K4: =Assumptions!J42 -> 113.17307 | L4: =Assumptions!K42 -> 132.22059 | M4: =Assumptions!L42 -> 158.09187 | N4: =Assumptions!M42 -> 189.66326 | ... P4: =Assumptions!O42 -> 250.35566
A5: Other Income | C5: 0.05 | D5: 0.04 | E5: 0.04 | F5: 0.06 | G5: 0.04 | H5: 0.05 | I5: 0.06 | J5: 0.08 | K5: 0.1 | L5: 0.12 | M5: 0.15 | N5: 0.18 | O5: 0.2 | P5: 0.25
A6: Total Income | C6: =C4+C5 -> 8.51 | D6: =D4+D5 -> 11.55 | E6: =E4+E5 -> 13.36 | F6: =F4+F5 -> 21.63 | G6: =G4+G5 -> 34.24 | H6: =H4+H5 -> 56.5146 | I6: =I4+I5 -> 75.05375 | J6: =J4+J5 -> 94.30125 | ... P6: =P4+P5 -> 250.60566
A8: Expenses:
A9: Employee Cost | C9: 1.11 | D9: 1.08 | E9: 2.08 | F9: 3.82 | G9: =ROUND(G4*Assumptions!F47,2) -> 5.64 | H9: =ROUND(H4*Assumptions!G47,2) -> 7.34 | I9: =ROUND(I4*Assumptions!H47,2) -> 9.37 | J9: =ROUND(J4*Assumptions!I47,2) -> 11.31 | K9: =ROUND(K4*Assumptions!J47,2) -> 13.01 | L9: =ROUND(L4*Assumptions!K47,2) -> 14.54 | M9: =ROUND(M4*Assumptions!L47,2) -> 17.39 | N9: =ROUND(N4*Assumptions!M47,2) -> 20.86 | ... P9: =ROUND(P4*Assumptions!O47,2) -> 27.54
A10: Other Expenses | C10: 3.47 | D10: 4.87 | E10: 4.22 | F10: 2.75 | G10: =ROUND(G4*Assumptions!F48,2) -> 2.22 | H10: =ROUND(H4*Assumptions!G48,2) -> 3.39 | I10: =ROUND(I4*Assumptions!H48,2) -> 4.87 | J10: =ROUND(J4*Assumptions!I48,2) -> 6.6 | K10: =ROUND(K4*Assumptions!J48,2) -> 8.49 | L10: =ROUND(L4*Assumptions!K48,2) -> 10.58 | M10: =ROUND(M4*Assumptions!L48,2) -> 12.65 | N10: =ROUND(N4*Assumptions!M48,2) -> 15.17 | ... P10: =ROUND(P4*Assumptions!O48,2) -> 20.03
A11: Total Expenditure | C11: =C9+C10 -> 4.58 | D11: =D9+D10 -> 5.95 | E11: =E9+E10 -> 6.3 | F11: =F9+F10 -> 6.57 | G11: =G9+G10 -> 7.86 | H11: =H9+H10 -> 10.73 | I11: =I9+I10 -> 14.24 | J11: =J9+J10 -> 17.91 | ... P11: =P9+P10 -> 47.57
A12: EBITDA | C12: =C6-C11 -> 3.93 | D12: =D6-D11 -> 5.6 | E12: =E6-E11 -> 7.06 | F12: =F6-F11 -> 15.06 | G12: =G6-G11 -> 26.38 | H12: =H6-H11 -> 45.7846 | I12: =I6-I11 -> 60.81375 | J12: =J6-J11 -> 76.39125 | ... P12: =P6-P11 -> 203.03566
A13: EBITDA Margin (%) | C13: =C12/C6 -> 0.46180964 | D13: =D12/D6 -> 0.48484848 | E13: =E12/E6 -> 0.52844311 | F13: =F12/F6 -> 0.6962552 | G13: =G12/G6 -> 0.77044393 | H13: =H12/H6 -> 0.81013756 | I13: =I12/I6 -> 0.81026931 | J13: =J12/J6 -> 0.81007675 | ... P13: =P12/P6 -> 0.81017986
A14: Interest / Finance Cost | C14: 0.51 | D14: 0.84 | E14: 1.42 | F14: 2.9 | G14: =Assumptions!F49 -> 2.5 | H14: =Assumptions!G49 -> 2.14 | I14: =Assumptions!H49 -> 3.42 | J14: =Assumptions!I49 -> 5.25 | K14: =Assumptions!J49 -> 7.72 | L14: =Assumptions!K49 -> 10.35 | M14: =Assumptions!L49 -> 13.53 | N14: =Assumptions!M49 -> 17.03 | ... P14: =Assumptions!O49 -> 26.21
A15: Depreciation | C15: 0.04 | D15: 0.03 | E15: 0.06 | F15: 0.08 | G15: 0.02 | H15: 0.03 | I15: 0.05 | J15: 0.07 | K15: 0.09 | L15: 0.11 | M15: 0.13 | N15: 0.15 | O15: 0.17 | P15: 0.19
A16: Provisions / Credit Costs | C16: 0.03 | D16: 0.08 | E16: 0 | F16: 0.2 | G16: =ROUND(Assumptions!F54*Assumptions!F57,2) -> 0.38 | H16: =ROUND(Assumptions!G54*Assumptions!G57,2) -> 0.61 | I16: =ROUND(Assumptions!H54*Assumptions!H57,2) -> 0.93 | J16: =ROUND(Assumptions!I54*Assumptions!I57,2) -> 1.23 | K16: =ROUND(Assumptions!J54*Assumptions!J57,2) -> 1.55 | L16: =ROUND(Assumptions!K54*Assumptions!K57,2) -> 1.85 | M16: =ROUND(Assumptions!L54*Assumptions!L57,2) -> 2.15 | N16: =ROUND(Assumptions!M54*Assumptions!M57,2) -> 2.65 | ... P16: =ROUND(Assumptions!O54*Assumptions!O57,2) -> 3.75
A17: Profit Before Tax (PBT) | C17: =C12-C14-C15-C16 -> 3.35 | D17: =D12-D14-D15-D16 -> 4.65 | E17: =E12-E14-E15-E16 -> 5.58 | F17: =F12-F14-F15-F16 -> 11.88 | G17: =G12-G14-G15-G16 -> 23.48 | H17: =H12-H14-H15-H16 -> 43.0046 | I17: =I12-I14-I15-I16 -> 56.41375 | J17: =J12-J14-J15-J16 -> 69.84125 | ... P17: =P12-P14-P15-P16 -> 172.88566
A18: Tax Expense | C18: 0.87 | D18: 1.19 | E18: 1.4 | F18: 3.2 | G18: =ROUND(G17*Assumptions!F51,2) -> 5.92 | H18: =ROUND(H17*Assumptions!G51,2) -> 10.84 | I18: =ROUND(I17*Assumptions!H51,2) -> 14.22 | J18: =ROUND(J17*Assumptions!I51,2) -> 17.6 | K18: =ROUND(K17*Assumptions!J51,2) -> 20.77 | L18: =ROUND(L17*Assumptions!K51,2) -> 23.92 | M18: =ROUND(M17*Assumptions!L51,2) -> 28.32 | N18: =ROUND(N17*Assumptions!M51,2) -> 33.76 | ... P18: =ROUND(P17*Assumptions!O51,2) -> 43.57
A19: Net Profit (PAT) | C19: =C17-C18 -> 2.48 | D19: =D17-D18 -> 3.46 | E19: =E17-E18 -> 4.18 | F19: =F17-F18 -> 8.68 | G19: =G17-G18 -> 17.56 | H19: =H17-H18 -> 32.1646 | I19: =I17-I18 -> 42.19375 | J19: =J17-J18 -> 52.24125 | ... P19: =P17-P18 -> 129.31566
A21: KEY MARGINS & RATIOS
A22: PAT Margin (%) | C22: =C19/C6 -> 0.29142186 | D22: =D19/D6 -> 0.2995671 | E22: =E19/E6 -> 0.31287425 | F22: =F19/F6 -> 0.4012945 | G22: =G19/G6 -> 0.51285047 | H22: =H19/H6 -> 0.56913789 | I22: =I19/I6 -> 0.56218044 | J22: =J19/J6 -> 0.55398258 | ... P22: =P19/P6 -> 0.51601252
A23: EPS (₹) | C23: =C19/2.88 -> 0.86111111 | D23: =D19/2.88 -> 1.2013889 | E23: =E19/3.38 -> 1.2366864 | F23: =F19/3.45 -> 2.515942 | G23: =G19/Assumptions!F56 -> 5.0898551 | H23: =H19/Assumptions!G56 -> 9.3230725 | I23: =I19/Assumptions!H56 -> 12.230072 | J23: =J19/Assumptions!I56 -> 15.142391 | K23: =K19/Assumptions!J56 -> 17.867558 | L23: =L19/Assumptions!K56 -> 20.576982 | M23: =M19/Assumptions!L56 -> 24.368657 | N23: =N19/Assumptions!M56 -> 29.050221 | ... P23: =P19/Assumptions!O56 -> 37.482799
A24: PAT Growth YoY (%) | D24: =IF(C19>0,(D19-C19)/C19,"") -> 0.39516129 | E24: =IF(D19>0,(E19-D19)/D19,"") -> 0.20809249 | F24: =IF(E19>0,(F19-E19)/E19,"") -> 1.076555 | G24: =IF(F19>0,(G19-F19)/F19,"") -> 1.0230415 | H24: =IF(G19>0,(H19-G19)/G19,"") -> 0.83169704 | I24: =IF(H19>0,(I19-H19)/H19,"") -> 0.31180708 | J24: =IF(I19>0,(J19-I19)/I19,"") -> 0.23812768 | K24: =IF(J19>0,(K19-J19)/J19,"") -> 0.17996937 | ... P24: =IF(O19>0,(P19-O19)/O19,"") -> 0.1302501

Sheet Balance Sheet
A1: EMERALD FINANCE LTD - CONSOLIDATED BALANCE SHEET
A2: (₹ Crores)
A3: ASSETS | C3: FY22 | D3: FY23 | E3: FY24 | F3: FY25 | G3: FY26E | H3: FY27E | I3: FY28E | J3: FY29E | K3: FY30E | L3: FY31E | M3: FY32E | N3: FY33E | O3: FY34E | P3: FY35E
A4: Cash & Bank Balances | C4: 1.98 | D4: 6.55 | E4: 2.97 | F4: 17.55 | G4: =G17-G5-G6-G7-G8 -> 25.426 | H4: =H17-H5-H6-H7-H8 -> 33.1231 | I4: =I17-I5-I6-I7-I8 -> 46.27685 | J4: =J17-J5-J6-J7-J8 -> 65.5456 | K4: =K17-K5-K6-K7-K8 -> 92.891175 | L4: =L17-L5-L6-L7-L8 -> 137.80926 | M4: =M17-M5-M6-M7-M8 -> 201.71363 | N4: =N17-N5-N6-N7-N8 -> 249.50439 | ... P4: =P17-P5-P6-P7-P8 -> 387.61836
A5: Loan Book / Advances (AUM) | C5: 42.01 | D5: 44.28 | E5: 55.04 | F5: 80.69 | G5: =Assumptions!F54 -> 95 | H5: =Assumptions!G54 -> 135 | I5: =Assumptions!H54 -> 185 | J5: =Assumptions!I54 -> 245 | K5: =Assumptions!J54 -> 310 | L5: =Assumptions!K54 -> 370 | M5: =Assumptions!L54 -> 430 | N5: =Assumptions!M54 -> 530 | ... P5: =Assumptions!O54 -> 750
A6: Investments | C6: 0.3 | D6: 0.47 | E6: 0.05 | F6: 0 | G6: 1 | H6: 1.5 | I6: 2 | J6: 2.5 | K6: 3 | L6: 3.5 | M6: 4 | N6: 5 | O6: 6 | P6: 7
A7: Fixed Assets (Net) | C7: 0.28 | D7: 0.26 | E7: 0.5 | F7: 0.68 | G7: 0.75 | H7: 0.85 | I7: 1 | J7: 1.2 | K7: 1.4 | L7: 1.6 | M7: 1.85 | N7: 2.1 | O7: 2.4 | P7: 2.7
A8: Other Assets | C8: 1.28 | D8: 1.29 | E8: 6.31 | F8: 6.8 | G8: 7.5 | H8: 8.5 | I8: 9.5 | J8: 11 | K8: 12.5 | L8: 14 | M8: 16 | N8: 18 | O8: 20 | P8: 22
A9: Total Assets | C9: =SUM(C4:C8) -> 45.85 | D9: =SUM(D4:D8) -> 52.85 | E9: =SUM(E4:E8) -> 64.87 | F9: =SUM(F4:F8) -> 105.72 | G9: =SUM(G4:G8) -> 129.676 | H9: =SUM(H4:H8) -> 178.9731 | I9: =SUM(I4:I8) -> 243.77685 | J9: =SUM(J4:J8) -> 325.2456 | ... P9: =SUM(P4:P8) -> 1169.3184
A11: LIABILITIES & EQUITY
A12: Equity Capital | C12: 29.04 | D12: 30.14 | E12: 30.14 | F12: 34.54 | G12: =Assumptions!F55 -> 34.54 | H12: =Assumptions!G55 -> 34.54 | I12: =Assumptions!H55 -> 34.54 | J12: =Assumptions!I55 -> 34.54 | K12: =Assumptions!J55 -> 34.54 | L12: =Assumptions!K55 -> 34.54 | M12: =Assumptions!L55 -> 34.54 | N12: =Assumptions!M55 -> 34.54 | ... P12: =Assumptions!O55 -> 34.54
A13: Reserves & Surplus | C13: 8.82 | D13: 13.29 | E13: 16.74 | F13: 49.99 | G13: =F13+'Income Statement'!G19-G28 -> 67.136 | H13: =G13+'Income Statement'!H19-H28 -> 98.7831 | I13: =H13+'Income Statement'!I19-I28 -> 140.28685 | J13: =I13+'Income Statement'!J19-J28 -> 191.6656 | K13: =J13+'Income Statement'!K19-K28 -> 252.10117 | L13: =K13+'Income Statement'!L19-L28 -> 321.53926 | M13: =L13+'Income Statement'!M19-M28 -> 403.71363 | N13: =M13+'Income Statement'!N19-N28 -> 501.69439 | ... P13: =O13+'Income Statement'!P19-P28 -> 736.79836
A14: Net Worth (Equity) | C14: =C12+C13 -> 37.86 | D14: =D12+D13 -> 43.43 | E14: =E12+E13 -> 46.88 | F14: =F12+F13 -> 84.53 | G14: =G12+G13 -> 101.676 | H14: =H12+H13 -> 133.3231 | I14: =I12+I13 -> 174.82685 | J14: =J12+J13 -> 226.2056 | ... P14: =P12+P13 -> 771.33836
A15: Borrowings (Total Debt) | C15: 4.85 | D15: 4.28 | E15: 14.53 | F15: 15.6 | G15: =ROUND(G14*Assumptions!F58,2) -> 20.34 | H15: =ROUND(H14*Assumptions!G58,2) -> 33.33 | I15: =ROUND(I14*Assumptions!H58,2) -> 52.45 | J15: =ROUND(J14*Assumptions!I58,2) -> 79.17 | K15: =ROUND(K14*Assumptions!J58,2) -> 108.92 | L15: =ROUND(L14*Assumptions!K58,2) -> 142.43 | M15: =ROUND(M14*Assumptions!L58,2) -> 184.07 | N15: =ROUND(N14*Assumptions!M58,2) -> 230.58 | ... P15: =ROUND(P14*Assumptions!O58,2) -> 347.1
A16: Other Liabilities | C16: =C9-C14-C15 -> 3.14 | D16: =D9-D14-D15 -> 5.14 | E16: =E9-E14-E15 -> 3.46 | F16: =F9-F14-F15 -> 5.59 | G16: =ROUND('Income Statement'!G19*0.173 + G5*0.04 + 'Income Statement'!G4*0.024, 2) -> 7.66 | H16: =ROUND('Income Statement'!H19*0.173 + H5*0.04 + 'Income Statement'!H4*0.024, 2) -> 12.32 | I16: =ROUND('Income Statement'!I19*0.173 + I5*0.04 + 'Income Statement'!I4*0.024, 2) -> 16.5 | J16: =ROUND('Income Statement'!J19*0.173 + J5*0.035 + 'Income Statement'!J4*0.024, 2) -> 19.87 | K16: =ROUND('Income Statement'!K19*0.173 + K5*0.035 + 'Income Statement'!K4*0.024, 2) -> 24.23 | L16: =ROUND('Income Statement'!L19*0.173 + L5*0.035 + 'Income Statement'!L4*0.024, 2) -> 28.4 | M16: =ROUND('Income Statement'!M19*0.173 + M5*0.03 + 'Income Statement'!M4*0.024, 2) -> 31.24 | N16: =ROUND('Income Statement'!N19*0.173 + N5*0.03 + 'Income Statement'!N4*0.024, 2) -> 37.79 | O16: =ROUND('Income Statement'!O19*0.173 + O5*0.03 + 'Income Statement'!O4*0.024, 2) -> 44.25 | P16: =ROUND('Income Statement'!P19*0.173 + P5*0.03 + 'Income Statement'!P4*0.024, 2) -> 50.88
A17: Total Liabilities & Equity | C17: =C14+C15+C16 -> 45.85 | D17: =D14+D15+D16 -> 52.85 | E17: =E14+E15+E16 -> 64.87 | F17: =F14+F15+F16 -> 105.72 | G17: =G14+G15+G16 -> 129.676 | H17: =H14+H15+H16 -> 178.9731 | I17: =I14+I15+I16 -> 243.77685 | J17: =J14+J15+J16 -> 325.2456 | ... P17: =P14+P15+P16 -> 1169.3184
A19: BS CHECK (Assets - L&E) | C19: =ROUND(C9-C17,2) -> 0 | D19: =ROUND(D9-D17,2) -> 0 | E19: =ROUND(E9-E17,2) -> 0 | F19: =ROUND(F9-F17,2) -> 0 | G19: =ROUND(G9-G17,2) -> 0 | H19: =ROUND(H9-H17,2) -> 0 | I19: =ROUND(I9-I17,2) -> 0 | J19: =ROUND(J9-J17,2) -> 0 | ... P19: =ROUND(P9-P17,2) -> 0
A21: KEY BS RATIOS
A22: ROE (%) | C22: ='Income Statement'!C19/C14 -> 0.06550449 | D22: ='Income Statement'!D19/D14 -> 0.079668432 | E22: ='Income Statement'!E19/E14 -> 0.089163823 | F22: ='Income Statement'!F19/F14 -> 0.10268544 | G22: ='Income Statement'!G19/G14 -> 0.17270546 | H22: ='Income Statement'!H19/H14 -> 0.24125302 | I22: ='Income Statement'!I19/I14 -> 0.24134594 | J22: ='Income Statement'!J19/J14 -> 0.23094587 | ... P22: ='Income Statement'!P19/P14 -> 0.16765101
A23: ROA (%) | C23: ='Income Statement'!C19/C9 -> 0.054089422 | D23: ='Income Statement'!D19/D9 -> 0.065468307 | E23: ='Income Statement'!E19/E9 -> 0.064436565 | F23: ='Income Statement'!F19/F9 -> 0.08210367 | G23: ='Income Statement'!G19/G9 -> 0.13541442 | H23: ='Income Statement'!H19/H9 -> 0.17971751 | I23: ='Income Statement'!I19/I9 -> 0.1730835 | J23: ='Income Statement'!J19/J9 -> 0.16062093 | ... P23: ='Income Statement'!P19/P9 -> 0.11059063
A24: Debt/Equity (x) | C24: =C15/C14 -> 0.12810354 | D24: =D15/D14 -> 0.09854939 | E24: =E15/E14 -> 0.30994027 | F24: =F15/F14 -> 0.18454986 | G24: =G15/G14 -> 0.20004721 | H24: =H15/H14 -> 0.24999419 | I24: =I15/I14 -> 0.30001113 | J24: =J15/J14 -> 0.34999134 | ... P24: =P15/P14 -> 0.44999707
A25: Book Value per Share (₹) | C25: =C14/2.88 -> 13.145833 | D25: =D14/2.88 -> 15.079861 | E25: =E14/3.38 -> 13.869822 | F25: =F14/3.45 -> 24.501449 | G25: =G14/Assumptions!F56 -> 29.471304 | H25: =H14/Assumptions!G56 -> 38.644377 | I25: =I14/Assumptions!H56 -> 50.674449 | J25: =J14/Assumptions!I56 -> 65.566841 | K25: =K14/Assumptions!J56 -> 83.084399 | L25: =L14/Assumptions!K56 -> 103.21138 | M25: =M14/Assumptions!L56 -> 127.03004 | N25: =N14/Assumptions!M56 -> 155.43026 | ... P25: =P14/Assumptions!O56 -> 223.57634
A27: Dividend Payout (₹/share) | C27: 0 | D27: 0 | E27: 0.06 | F27: 0.09 | G27: 0.12 | H27: 0.15 | I27: 0.2 | J27: 0.25 | K27: 0.35 | L27: 0.45 | M27: 0.55 | N27: 0.65 | O27: 1 | P27: 1.5
A28: Total Dividends (₹ Cr) | C28: 0 | D28: 0 | E28: =E27*3.38 -> 0.2028 | F28: =F27*3.45 -> 0.3105 | G28: =G27*Assumptions!F56 -> 0.414 | H28: =H27*Assumptions!G56 -> 0.5175 | I28: =I27*Assumptions!H56 -> 0.69 | J28: =J27*Assumptions!I56 -> 0.8625 | K28: =K27*Assumptions!J56 -> 1.2075 | L28: =L27*Assumptions!K56 -> 1.5525 | M28: =M27*Assumptions!L56 -> 1.8975 | N28: =N27*Assumptions!M56 -> 2.2425 | ... P28: =P27*Assumptions!O56 -> 5.175

Sheet Cash Flow
A1: EMERALD FINANCE LTD - CONSOLIDATED CASH FLOW STATEMENT
A2: (₹ Crores)
A3: Particulars | C3: FY22 | D3: FY23 | E3: FY24 | F3: FY25 | G3: FY26E | H3: FY27E | I3: FY28E | J3: FY29E | K3: FY30E | L3: FY31E | M3: FY32E | N3: FY33E | O3: FY34E | P3: FY35E
A4: A. CASH FROM OPERATIONS
A5: Net Profit (PAT) | C5: ='Income Statement'!C19 -> 2.48 | D5: ='Income Statement'!D19 -> 3.46 | E5: ='Income Statement'!E19 -> 4.18 | F5: ='Income Statement'!F19 -> 8.68 | G5: ='Income Statement'!G19 -> 17.56 | H5: ='Income Statement'!H19 -> 32.1646 | I5: ='Income Statement'!I19 -> 42.19375 | J5: ='Income Statement'!J19 -> 52.24125 | ... P5: ='Income Statement'!P19 -> 129.31566
A6: (+) Depreciation | C6: 0.04 | D6: 0.03 | E6: 0.06 | F6: ='Income Statement'!F15 -> 0.08 | G6: ='Income Statement'!G15 -> 0.02 | H6: ='Income Statement'!H15 -> 0.03 | I6: ='Income Statement'!I15 -> 0.05 | J6: ='Income Statement'!J15 -> 0.07 | K6: ='Income Statement'!K15 -> 0.09 | L6: ='Income Statement'!L15 -> 0.11 | M6: ='Income Statement'!M15 -> 0.13 | ... P6: ='Income Statement'!P15 -> 0.19
A7: (+) Provisions | C7: 0.03 | D7: 0.08 | E7: 0 | F7: ='Income Statement'!F16 -> 0.2 | G7: ='Income Statement'!G16 -> 0.38 | H7: ='Income Statement'!H16 -> 0.61 | I7: ='Income Statement'!I16 -> 0.93 | J7: ='Income Statement'!J16 -> 1.23 | K7: ='Income Statement'!K16 -> 1.55 | L7: ='Income Statement'!L16 -> 1.85 | M7: ='Income Statement'!M16 -> 2.15 | ... P7: ='Income Statement'!P16 -> 3.75
A8: (-) Change in Loan Book | C8: -42.01 | D8: =-('Balance Sheet'!D5-'Balance Sheet'!C5) -> -2.27 | E8: =-('Balance Sheet'!E5-'Balance Sheet'!D5) -> -10.76 | F8: =-('Balance Sheet'!F5-'Balance Sheet'!E5) -> -25.65 | G8: =-('Balance Sheet'!G5-'Balance Sheet'!F5) -> -14.31 | H8: =-('Balance Sheet'!H5-'Balance Sheet'!G5) -> -40 | I8: =-('Balance Sheet'!I5-'Balance Sheet'!H5) -> -50 | J8: =-('Balance Sheet'!J5-'Balance Sheet'!I5) -> -60 | K8: =-('Balance Sheet'!K5-'Balance Sheet'!J5) -> -65 | ... P8: =-('Balance Sheet'!P5-'Balance Sheet'!O5) -> -110
A9: (-) Change in Other WC | C9: 37.76 | D9: ='Balance Sheet'!D4-'Balance Sheet'!C4-(D5+D6+D7+D8)-D15-D21 -> 2.92 | E9: ='Balance Sheet'!E4-'Balance Sheet'!D4-(E5+E6+E7+E8)-E15-E21 -> -7.2272 | F9: ='Balance Sheet'!F4-'Balance Sheet'!E4-(F5+F6+F7+F8)-F15-F21 -> 26.3205 | G9: =('Balance Sheet'!G16-'Balance Sheet'!F16)-('Balance Sheet'!G8-'Balance Sheet'!F8) -> 1.37 | H9: =('Balance Sheet'!H16-'Balance Sheet'!G16)-('Balance Sheet'!H8-'Balance Sheet'!G8) -> 3.66 | I9: =('Balance Sheet'!I16-'Balance Sheet'!H16)-('Balance Sheet'!I8-'Balance Sheet'!H8) -> 3.18 | J9: =('Balance Sheet'!J16-'Balance Sheet'!I16)-('Balance Sheet'!J8-'Balance Sheet'!I8) -> 1.87 | K9: =('Balance Sheet'!K16-'Balance Sheet'!J16)-('Balance Sheet'!K8-'Balance Sheet'!J8) -> 2.86 | L9: =('Balance Sheet'!L16-'Balance Sheet'!K16)-('Balance Sheet'!L8-'Balance Sheet'!K8) -> 2.67 | M9: =('Balance Sheet'!M16-'Balance Sheet'!L16)-('Balance Sheet'!M8-'Balance Sheet'!L8) -> 0.84 | N9: =('Balance Sheet'!N16-'Balance Sheet'!M16)-('Balance Sheet'!N8-'Balance Sheet'!M8) -> 4.55 | ... P9: =('Balance Sheet'!P16-'Balance Sheet'!O16)-('Balance Sheet'!P8-'Balance Sheet'!O8) -> 4.63
A10: Cash from Operations (CFO) | C10: =SUM(C5:C9) -> -1.7 | D10: =SUM(D5:D9) -> 4.22 | E10: =SUM(E5:E9) -> -13.7472 | F10: =SUM(F5:F9) -> 9.6305 | G10: =SUM(G5:G9) -> 5.02 | H10: =SUM(H5:H9) -> -3.5354 | I10: =SUM(I5:I9) -> -3.64625 | J10: =SUM(J5:J9) -> -4.58875 | ... P10: =SUM(P5:P9) -> 27.885656
A12: B. CASH FROM INVESTING
A13: (-) Capex / Fixed Assets | C13: -0.28 | D13: =-('Balance Sheet'!D7-'Balance Sheet'!C7+'Income Statement'!D15) -> -0.01 | E13: =-('Balance Sheet'!E7-'Balance Sheet'!D7+'Income Statement'!E15) -> -0.3 | F13: =-('Balance Sheet'!F7-'Balance Sheet'!E7+'Income Statement'!F15) -> -0.26 | G13: =-('Balance Sheet'!G7-'Balance Sheet'!F7+'Income Statement'!G15) -> -0.09 | H13: =-('Balance Sheet'!H7-'Balance Sheet'!G7+'Income Statement'!H15) -> -0.13 | I13: =-('Balance Sheet'!I7-'Balance Sheet'!H7+'Income Statement'!I15) -> -0.2 | J13: =-('Balance Sheet'!J7-'Balance Sheet'!I7+'Income Statement'!J15) -> -0.27 | K13: =-('Balance Sheet'!K7-'Balance Sheet'!J7+'Income Statement'!K15) -> -0.29 | ... P13: =-('Balance Sheet'!P7-'Balance Sheet'!O7+'Income Statement'!P15) -> -0.49
A14: (-) Change in Investments | C14: -0.3 | D14: =-('Balance Sheet'!D6-'Balance Sheet'!C6) -> -0.17 | E14: =-('Balance Sheet'!E6-'Balance Sheet'!D6) -> 0.42 | F14: =-('Balance Sheet'!F6-'Balance Sheet'!E6) -> 0.05 | G14: =-('Balance Sheet'!G6-'Balance Sheet'!F6) -> -1 | H14: =-('Balance Sheet'!H6-'Balance Sheet'!G6) -> -0.5 | I14: =-('Balance Sheet'!I6-'Balance Sheet'!H6) -> -0.5 | J14: =-('Balance Sheet'!J6-'Balance Sheet'!I6) -> -0.5 | K14: =-('Balance Sheet'!K6-'Balance Sheet'!J6) -> -0.5 | ... P14: =-('Balance Sheet'!P6-'Balance Sheet'!O6) -> -1
A15: Cash from Investing (CFI) | C15: =C13+C14 -> -0.58 | D15: =D13+D14 -> -0.18 | E15: =E13+E14 -> 0.12 | F15: =F13+F14 -> -0.21 | G15: =G13+G14 -> -1.09 | H15: =H13+H14 -> -0.63 | I15: =I13+I14 -> -0.7 | J15: =J13+J14 -> -0.77 | ... P15: =P13+P14 -> -1.49
A17: C. CASH FROM FINANCING
A18: Net Borrowings | C18: 4.85 | D18: ='Balance Sheet'!D15-'Balance Sheet'!C15 -> -0.57 | E18: ='Balance Sheet'!E15-'Balance Sheet'!D15 -> 10.25 | F18: ='Balance Sheet'!F15-'Balance Sheet'!E15 -> 1.07 | G18: ='Balance Sheet'!G15-'Balance Sheet'!F15 -> 4.74 | H18: ='Balance Sheet'!H15-'Balance Sheet'!G15 -> 12.99 | I18: ='Balance Sheet'!I15-'Balance Sheet'!H15 -> 19.12 | J18: ='Balance Sheet'!J15-'Balance Sheet'!I15 -> 26.72 | K18: ='Balance Sheet'!K15-'Balance Sheet'!J15 -> 29.75 | ... P18: ='Balance Sheet'!P15-'Balance Sheet'!O15 -> 55.86
A19: Equity Raised / (Buyback) | C19: 29.04 | D19: ='Balance Sheet'!D12-'Balance Sheet'!C12 -> 1.1 | E19: ='Balance Sheet'!E12-'Balance Sheet'!D12 -> 0 | F19: ='Balance Sheet'!F12-'Balance Sheet'!E12 -> 4.4 | G19: ='Balance Sheet'!G12-'Balance Sheet'!F12 -> 0 | H19: ='Balance Sheet'!H12-'Balance Sheet'!G12 -> 0 | I19: ='Balance Sheet'!I12-'Balance Sheet'!H12 -> 0 | J19: ='Balance Sheet'!J12-'Balance Sheet'!I12 -> 0 | K19: ='Balance Sheet'!K12-'Balance Sheet'!J12 -> 0 | ... P19: ='Balance Sheet'!P12-'Balance Sheet'!O12 -> 0
A20: (-) Dividends Paid | C20: 0 | D20: 0 | E20: =-'Balance Sheet'!E28 -> -0.2028 | F20: =-'Balance Sheet'!F28 -> -0.3105 | G20: =-'Balance Sheet'!G28 -> -0.414 | H20: =-'Balance Sheet'!H28 -> -0.5175 | I20: =-'Balance Sheet'!I28 -> -0.69 | J20: =-'Balance Sheet'!J28 -> -0.8625 | K20: =-'Balance Sheet'!K28 -> -1.2075 | L20: =-'Balance Sheet'!L28 -> -1.5525 | ... P20: =-'Balance Sheet'!P28 -> -5.175
A21: Cash from Financing (CFF) | C21: =C18+C19+C20 -> 33.89 | D21: =D18+D19+D20 -> 0.53 | E21: =E18+E19+E20 -> 10.0472 | F21: =F18+F19+F20 -> 5.1595 | G21: =G18+G19+G20 -> 4.326 | H21: =H18+H19+H20 -> 12.4725 | I21: =I18+I19+I20 -> 18.43 | J21: =J18+J19+J20 -> 25.8575 | ... P21: =P18+P19+P20 -> 50.685
A22: Net Change in Cash | C22: =C10+C15+C21 -> 31.61 | D22: =D10+D15+D21 -> 4.57 | E22: =E10+E15+E21 -> -3.58 | F22: =F10+F15+F21 -> 14.58 | G22: =G10+G15+G21 -> 8.256 | H22: =H10+H15+H21 -> 8.3071 | I22: =I10+I15+I21 -> 14.08375 | J22: =J10+J15+J21 -> 20.49875 | ... P22: =P10+P15+P21 -> 77.080656

Sheet Summary & Valuation
A1: EMERALD FINANCE LTD - SUMMARY & VALUATION
A2: (₹ Crores unless stated)
A3: KEY FINANCIAL SUMMARY | C3: FY22 | D3: FY23 | E3: FY24 | F3: FY25 | G3: FY26E | H3: FY27E | I3: FY28E | J3: FY29E | K3: FY30E | L3: FY31E | M3: FY32E | N3: FY33E | O3: FY34E | P3: FY35E
A4: Total Income (₹ Cr) | C4: ='Income Statement'!C6 -> 8.51 | D4: ='Income Statement'!D6 -> 11.55 | E4: ='Income Statement'!E6 -> 13.36 | F4: ='Income Statement'!F6 -> 21.63 | G4: ='Income Statement'!G6 -> 34.24 | H4: ='Income Statement'!H6 -> 56.5146 | I4: ='Income Statement'!I6 -> 75.05375 | J4: ='Income Statement'!J6 -> 94.30125 | ... P4: ='Income Statement'!P6 -> 250.60566
A5: EBITDA (₹ Cr) | C5: ='Income Statement'!C12 -> 3.93 | D5: ='Income Statement'!D12 -> 5.6 | E5: ='Income Statement'!E12 -> 7.06 | F5: ='Income Statement'!F12 -> 15.06 | G5: ='Income Statement'!G12 -> 26.38 | H5: ='Income Statement'!H12 -> 45.7846 | I5: ='Income Statement'!I12 -> 60.81375 | J5: ='Income Statement'!J12 -> 76.39125 | ... P5: ='Income Statement'!P12 -> 203.03566
A6: Net Profit (PAT) (₹ Cr) | C6: ='Income Statement'!C19 -> 2.48 | D6: ='Income Statement'!D19 -> 3.46 | E6: ='Income Statement'!E19 -> 4.18 | F6: ='Income Statement'!F19 -> 8.68 | G6: ='Income Statement'!G19 -> 17.56 | H6: ='Income Statement'!H19 -> 32.1646 | I6: ='Income Statement'!I19 -> 42.19375 | J6: ='Income Statement'!J19 -> 52.24125 | ... P6: ='Income Statement'!P19 -> 129.31566
A7: EPS (₹) | C7: ='Income Statement'!C23 -> 0.86111111 | D7: ='Income Statement'!D23 -> 1.2013889 | E7: ='Income Statement'!E23 -> 1.2366864 | F7: ='Income Statement'!F23 -> 2.515942 | G7: ='Income Statement'!G23 -> 5.0898551 | H7: ='Income Statement'!H23 -> 9.3230725 | I7: ='Income Statement'!I23 -> 12.230072 | J7: ='Income Statement'!J23 -> 15.142391 | ... P7: ='Income Statement'!P23 -> 37.482799
A8: BVPS (₹) | C8: ='Balance Sheet'!C25 -> 13.145833 | D8: ='Balance Sheet'!D25 -> 15.079861 | E8: ='Balance Sheet'!E25 -> 13.869822 | F8: ='Balance Sheet'!F25 -> 24.501449 | G8: ='Balance Sheet'!G25 -> 29.471304 | H8: ='Balance Sheet'!H25 -> 38.644377 | I8: ='Balance Sheet'!I25 -> 50.674449 | J8: ='Balance Sheet'!J25 -> 65.566841 | ... P8: ='Balance Sheet'!P25 -> 223.57634
A9: AUM / Loan Book (₹ Cr) | C9: ='Balance Sheet'!C5 -> 42.01 | D9: ='Balance Sheet'!D5 -> 44.28 | E9: ='Balance Sheet'!E5 -> 55.04 | F9: ='Balance Sheet'!F5 -> 80.69 | G9: ='Balance Sheet'!G5 -> 95 | H9: ='Balance Sheet'!H5 -> 135 | I9: ='Balance Sheet'!I5 -> 185 | J9: ='Balance Sheet'!J5 -> 245 | ... P9: ='Balance Sheet'!P5 -> 750
A11: KEY RATIOS
A12: Revenue Growth (%) | D12: =(D4-C4)/C4 -> 0.35722679 | E12: =(E4-D4)/D4 -> 0.15670996 | F12: =(F4-E4)/E4 -> 0.61901198 | G12: =(G4-F4)/F4 -> 0.58298659 | H12: =(H4-G4)/G4 -> 0.65054322 | I12: =(I4-H4)/H4 -> 0.32804178 | J12: =(J4-I4)/I4 -> 0.25644954 | K12: =(K4-J4)/J4 -> 0.20118318 | ... P12: =(P4-O4)/O4 -> 0.14283962
A13: PAT Growth (%) | D13: =(D6-C6)/C6 -> 0.39516129 | E13: =(E6-D6)/D6 -> 0.20809249 | F13: =(F6-E6)/E6 -> 1.076555 | G13: =(G6-F6)/F6 -> 1.0230415 | H13: =(H6-G6)/G6 -> 0.83169704 | I13: =(I6-H6)/H6 -> 0.31180708 | J13: =(J6-I6)/I6 -> 0.23812768 | K13: =(K6-J6)/J6 -> 0.17996937 | ... P13: =(P6-O6)/O6 -> 0.1302501
A14: EBITDA Margin (%) | C14: =C5/C4 -> 0.46180964 | D14: =D5/D4 -> 0.48484848 | E14: =E5/E4 -> 0.52844311 | F14: =F5/F4 -> 0.6962552 | G14: =G5/G4 -> 0.77044393 | H14: =H5/H4 -> 0.81013756 | I14: =I5/I4 -> 0.81026931 | J14: =J5/J4 -> 0.81007675 | ... P14: =P5/P4 -> 0.81017986
A15: PAT Margin (%) | C15: =C6/C4 -> 0.29142186 | D15: =D6/D4 -> 0.2995671 | E15: =E6/E4 -> 0.31287425 | F15: =F6/F4 -> 0.4012945 | G15: =G6/G4 -> 0.51285047 | H15: =H6/H4 -> 0.56913789 | I15: =I6/I4 -> 0.56218044 | J15: =J6/J4 -> 0.55398258 | ... P15: =P6/P4 -> 0.51601252
A16: ROE (%) | C16: ='Balance Sheet'!C22 -> 0.06550449 | D16: ='Balance Sheet'!D22 -> 0.079668432 | E16: ='Balance Sheet'!E22 -> 0.089163823 | F16: ='Balance Sheet'!F22 -> 0.10268544 | G16: ='Balance Sheet'!G22 -> 0.17270546 | H16: ='Balance Sheet'!H22 -> 0.24125302 | I16: ='Balance Sheet'!I22 -> 0.24134594 | J16: ='Balance Sheet'!J22 -> 0.23094587 | ... P16: ='Balance Sheet'!P22 -> 0.16765101
A17: ROA (%) | C17: ='Balance Sheet'!C23 -> 0.054089422 | D17: ='Balance Sheet'!D23 -> 0.065468307 | E17: ='Balance Sheet'!E23 -> 0.064436565 | F17: ='Balance Sheet'!F23 -> 0.08210367 | G17: ='Balance Sheet'!G23 -> 0.13541442 | H17: ='Balance Sheet'!H23 -> 0.17971751 | I17: ='Balance Sheet'!I23 -> 0.1730835 | J17: ='Balance Sheet'!J23 -> 0.16062093 | ... P17: ='Balance Sheet'!P23 -> 0.11059063
A18: Debt/Equity (x) | C18: ='Balance Sheet'!C24 -> 0.12810354 | D18: ='Balance Sheet'!D24 -> 0.09854939 | E18: ='Balance Sheet'!E24 -> 0.30994027 | F18: ='Balance Sheet'!F24 -> 0.18454986 | G18: ='Balance Sheet'!G24 -> 0.20004721 | H18: ='Balance Sheet'!H24 -> 0.24999419 | I18: ='Balance Sheet'!I24 -> 0.30001113 | J18: ='Balance Sheet'!J24 -> 0.34999134 | ... P18: ='Balance Sheet'!P24 -> 0.44999707
A19: AUM Growth (%) | D19: =(D9-C9)/C9 -> 0.054034754 | E19: =(E9-D9)/D9 -> 0.2429991 | F19: =(F9-E9)/E9 -> 0.46602471 | G19: =(G9-F9)/F9 -> 0.1773454 | H19: =(H9-G9)/G9 -> 0.42105263 | I19: =(I9-H9)/H9 -> 0.37037037 | J19: =(J9-I9)/I9 -> 0.32432432 | K19: =(K9-J9)/J9 -> 0.26530612 | ... P19: =(P9-O9)/O9 -> 0.171875
A20: CFO (₹ Cr) | C20: ='Cash Flow'!C10 -> -1.7 | D20: ='Cash Flow'!D10 -> 4.22 | E20: ='Cash Flow'!E10 -> -13.7472 | F20: ='Cash Flow'!F10 -> 9.6305 | G20: ='Cash Flow'!G10 -> 5.02 | H20: ='Cash Flow'!H10 -> -3.5354 | I20: ='Cash Flow'!I10 -> -3.64625 | J20: ='Cash Flow'!J10 -> -4.58875 | ... P20: ='Cash Flow'!P10 -> 27.885656
A22: VALUATION
A24: RESIDUAL INCOME VALUATION | F24: FY26E | G24: FY27E | H24: FY28E | I24: FY29E | J24: FY30E | K24: FY30E | L24: FY31E | M24: FY32E | N24: FY33E | O24: FY34E | P24: FY35E
A25: Cost of Equity (Ke) | B25: 0.14
A26: Terminal Growth Rate (g) | B26: 0.05
A27: Current BVPS (FY26E) (₹) | B27: =G8 -> 29.471304 | H27: ='Cash Flow'!H22 -> 8.3071 | I27: ='Cash Flow'!I22 -> 14.08375 | J27: ='Cash Flow'!J22 -> 20.49875 | K27: ='Cash Flow'!K22 -> 28.895575 | L27: ='Cash Flow'!L22 -> 46.768088 | M27: ='Cash Flow'!M22 -> 66.054366 | N27: ='Cash Flow'!N22 -> 50.440763 | O27: ='Cash Flow'!O22 -> 67.983311 | P27: ='Cash Flow'!P22 -> 77.080656
A28: Excess Return per Share (₹) | G28: =(G16-$B$25)*F8 -> 0.80133108 | H28: =(H16-$B$25)*G8 -> 2.9840585 | I28: =(I16-$B$25)*H8 -> 3.9164506 | J28: =(J16-$B$25)*I8 -> 4.6086321 | K28: =(K16-$B$25)*J8 -> 4.920995 | L28: =(L16-$B$25)*K8 -> 4.9325027 | M28: =(M16-$B$25)*L8 -> 5.3498398 | N28: =(N16-$B$25)*M8 -> 5.9579588 | ... P28: =(P16-$B$25)*O8 -> 5.1871511
A29: Discount Factor | G29: =1/(1+$B$25)^1 -> 0.87719298 | H29: =1/(1+$B$25)^2 -> 0.76946753 | I29: =1/(1+$B$25)^3 -> 0.67497152 | J29: =1/(1+$B$25)^4 -> 0.59208028 | K29: =1/(1+$B$25)^5 -> 0.51936866 | L29: =1/(1+$B$25)^6 -> 0.45558655 | M29: =1/(1+$B$25)^7 -> 0.39963732 | N29: =1/(1+$B$25)^8 -> 0.35055905 | O29: =1/(1+$B$25)^9 -> 0.30750794 | P29: =1/(1+$B$25)^10 -> 0.26974381
A30: PV of Excess Return (₹) | G30: =G28*G29 -> 0.702922 | H30: =H28*H29 -> 2.2961361 | I30: =I28*I29 -> 2.6434926 | J30: =J28*J29 -> 2.7286802 | K30: =K28*K29 -> 2.5558106 | L30: =L28*L29 -> 2.2471819 | M30: =M28*M29 -> 2.1379956 | N30: =N28*N29 -> 2.0886164 | ... P30: =P28*P29 -> 1.3992019
A31: PV of Terminal Excess (₹) | P31: =P28*(1+$B$26)/($B$25-$B$26)*P29 -> 16.324022
A32: Residual Income Value / Share (₹) | G32: =$B$27+SUM(G30:P30)+P31 -> 66.353428
A33: Shares Outstanding (Cr) | G33: =Assumptions!F56 -> 3.45
A34: Equity Value (₹ Cr) | G34: =G32*G33 -> 228.91933
A35: RI Fair Value per Share (₹) | G35: =G32 -> 66.353428
A36: DCF (FCFE) VALUATION | G36: FY26E | H36: FY27E | I36: FY28E | J36: FY29E | K36: FY30E | L36: FY31E | M36: FY32E | N36: FY33E | O36: FY34E | P36: FY35E
A37: Cost of Equity (Ke) | B37: =B25 -> 0.14
A38: Terminal Growth Rate (g) | B38: =B26 -> 0.05
A39: Shares Outstanding (Cr) | B39: =G33 -> 3.45
A41: FCFE BUILD-UP
A42: Cash from Operations (CFO) | G42: ='Cash Flow'!G10 -> 5.02 | H42: ='Cash Flow'!H10 -> -3.5354 | I42: ='Cash Flow'!I10 -> -3.64625 | J42: ='Cash Flow'!J10 -> -4.58875 | K42: ='Cash Flow'!K10 -> 1.143075 | L42: ='Cash Flow'!L10 -> 15.620588 | M42: ='Cash Flow'!M10 -> 27.191866 | N42: ='Cash Flow'!N10 -> 7.5732633 | ... P42: ='Cash Flow'!P10 -> 27.885656
A43: Cash from Investing (CFI) | G43: ='Cash Flow'!G15 -> -1.09 | H43: ='Cash Flow'!H15 -> -0.63 | I43: ='Cash Flow'!I15 -> -0.7 | J43: ='Cash Flow'!J15 -> -0.77 | K43: ='Cash Flow'!K15 -> -0.79 | L43: ='Cash Flow'!L15 -> -0.81 | M43: ='Cash Flow'!M15 -> -0.88 | N43: ='Cash Flow'!N15 -> -1.4 | ... P43: ='Cash Flow'!P15 -> -1.49
A44: (+) Net Borrowings | G44: ='Cash Flow'!G18 -> 4.74 | H44: ='Cash Flow'!H18 -> 12.99 | I44: ='Cash Flow'!I18 -> 19.12 | J44: ='Cash Flow'!J18 -> 26.72 | K44: ='Cash Flow'!K18 -> 29.75 | L44: ='Cash Flow'!L18 -> 33.51 | M44: ='Cash Flow'!M18 -> 41.64 | N44: ='Cash Flow'!N18 -> 46.51 | ... P44: ='Cash Flow'!P18 -> 55.86
...

Sheet Charts
A1: EMERALD FINANCE LTD - KEY METRICS DASHBOARD
A3: Year | B3: Total Income (₹ Cr) | C3: PAT (₹ Cr) | D3: EBITDA (₹ Cr)
A4: FY22 | B4: ='Income Statement'!C6 -> 8.51 | C4: ='Income Statement'!C19 -> 2.48 | D4: ='Income Statement'!C12 -> 3.93
A5: FY23 | B5: ='Income Statement'!D6 -> 11.55 | C5: ='Income Statement'!D19 -> 3.46 | D5: ='Income Statement'!D12 -> 5.6
A6: FY24 | B6: ='Income Statement'!E6 -> 13.36 | C6: ='Income Statement'!E19 -> 4.18 | D6: ='Income Statement'!E12 -> 7.06
A7: FY25 | B7: ='Income Statement'!F6 -> 21.63 | C7: ='Income Statement'!F19 -> 8.68 | D7: ='Income Statement'!F12 -> 15.06
A8: FY26E | B8: ='Income Statement'!G6 -> 34.24 | C8: ='Income Statement'!G19 -> 17.56 | D8: ='Income Statement'!G12 -> 26.38
A9: FY27E | B9: ='Income Statement'!H6 -> 56.5146 | C9: ='Income Statement'!H19 -> 32.1646 | D9: ='Income Statement'!H12 -> 45.7846
A10: FY28E | B10: ='Income Statement'!I6 -> 75.05375 | C10: ='Income Statement'!I19 -> 42.19375 | D10: ='Income Statement'!I12 -> 60.81375
A11: FY29E | B11: ='Income Statement'!J6 -> 94.30125 | C11: ='Income Statement'!J19 -> 52.24125 | D11: ='Income Statement'!J12 -> 76.39125
A12: FY30E | B12: ='Income Statement'!K6 -> 113.27307 | C12: ='Income Statement'!K19 -> 61.643075 | D12: ='Income Statement'!K12 -> 91.773075
A13: FY31E | B13: ='Income Statement'!L6 -> 132.34059 | C13: ='Income Statement'!L19 -> 70.990588 | D13: ='Income Statement'!L12 -> 107.22059
A14: FY32E | B14: ='Income Statement'!M6 -> 158.24187 | C14: ='Income Statement'!M19 -> 84.071866 | D14: ='Income Statement'!M12 -> 128.20187
A15: FY33E | B15: ='Income Statement'!N6 -> 189.84326 | C15: ='Income Statement'!N19 -> 100.22326 | D15: ='Income Statement'!N12 -> 153.81326
A16: FY34E | B16: ='Income Statement'!O6 -> 219.28331 | C16: ='Income Statement'!O19 -> 114.41331 | D16: ='Income Statement'!O12 -> 177.65331
A17: FY35E | B17: ='Income Statement'!P6 -> 250.60566 | C17: ='Income Statement'!P19 -> 129.31566 | D17: ='Income Statement'!P12 -> 203.03566
A20: Year | B20: EBITDA Margin (%) | C20: PAT Margin (%) | D20: ROE (%)
A21: FY22 | B21: ='Income Statement'!C13 -> 0.46180964 | C21: ='Income Statement'!C22 -> 0.29142186 | D21: ='Summary & Valuation'!C16 -> 0.06550449
A22: FY23 | B22: ='Income Statement'!D13 -> 0.48484848 | C22: ='Income Statement'!D22 -> 0.2995671 | D22: ='Summary & Valuation'!D16 -> 0.079668432
A23: FY24 | B23: ='Income Statement'!E13 -> 0.52844311 | C23: ='Income Statement'!E22 -> 0.31287425 | D23: ='Summary & Valuation'!E16 -> 0.089163823
A24: FY25 | B24: ='Income Statement'!F13 -> 0.6962552 | C24: ='Income Statement'!F22 -> 0.4012945 | D24: ='Summary & Valuation'!F16 -> 0.10268544
A25: FY26E | B25: ='Income Statement'!G13 -> 0.77044393 | C25: ='Income Statement'!G22 -> 0.51285047 | D25: ='Summary & Valuation'!G16 -> 0.17270546
A26: FY27E | B26: ='Income Statement'!H13 -> 0.81013756 | C26: ='Income Statement'!H22 -> 0.56913789 | D26: ='Summary & Valuation'!H16 -> 0.24125302
A27: FY28E | B27: ='Income Statement'!I13 -> 0.81026931 | C27: ='Income Statement'!I22 -> 0.56218044 | D27: ='Summary & Valuation'!I16 -> 0.24134594
A28: FY29E | B28: ='Income Statement'!J13 -> 0.81007675 | C28: ='Income Statement'!J22 -> 0.55398258 | D28: ='Summary & Valuation'!J16 -> 0.23094587
A29: FY30E | B29: ='Income Statement'!K13 -> 0.8101932 | C29: ='Income Statement'!K22 -> 0.54419883 | D29: ='Summary & Valuation'!K16 -> 0.21505311
A30: FY31E | B30: ='Income Statement'!L13 -> 0.81018673 | C30: ='Income Statement'!L22 -> 0.5364234 | D30: ='Summary & Valuation'!L16 -> 0.19936738
A31: FY32E | B31: ='Income Statement'!M13 -> 0.81016402 | C31: ='Income Statement'!M22 -> 0.53128713 | D31: ='Summary & Valuation'!M16 -> 0.19183382
A32: FY33E | B32: ='Income Statement'!N13 -> 0.81021186 | C32: ='Income Statement'!N22 -> 0.52792636 | D32: ='Summary & Valuation'!N16 -> 0.18690197
A33: FY34E | B33: ='Income Statement'!O13 -> 0.81015427 | C33: ='Income Statement'!O22 -> 0.52176023 | D33: ='Summary & Valuation'!O16 -> 0.17678263
A34: FY35E | B34: ='Income Statement'!P13 -> 0.81017986 | C34: ='Income Statement'!P22 -> 0.51601252 | D34: ='Summary & Valuation'!P16 -> 0.16765101
A37: Year | B37: EPS (₹) | C37: BVPS (₹)
A38: FY22 | B38: ='Summary & Valuation'!C7 -> 0.86111111 | C38: ='Summary & Valuation'!C8 -> 13.145833
A39: FY23 | B39: ='Summary & Valuation'!D7 -> 1.2013889 | C39: ='Summary & Valuation'!D8 -> 15.079861
A40: FY24 | B40: ='Summary & Valuation'!E7 -> 1.2366864 | C40: ='Summary & Valuation'!E8 -> 13.869822
A41: FY25 | B41: ='Summary & Valuation'!F7 -> 2.515942 | C41: ='Summary & Valuation'!F8 -> 24.501449
A42: FY26E | B42: ='Summary & Valuation'!G7 -> 5.0898551 | C42: ='Summary & Valuation'!G8 -> 29.471304
A43: FY27E | B43: ='Summary & Valuation'!H7 -> 9.3230725 | C43: ='Summary & Valuation'!H8 -> 38.644377
A44: FY28E | B44: ='Summary & Valuation'!I7 -> 12.230072 | C44: ='Summary & Valuation'!I8 -> 50.674449
A45: FY29E | B45: ='Summary & Valuation'!J7 -> 15.142391 | C45: ='Summary & Valuation'!J8 -> 65.566841
...
