Workbook

Sheet Assumptions & Thesis
A1: NINtec Systems Ltd — Key Assumptions & Investment Thesis
A2: 📌 Editable assumptions are in blue font on yellow background | Black font = formulas/calculated | All values in ₹ Cr unless stated
A3: INVESTMENT THESIS & KEY OBSERVATIONS
A4: 1. NINtec serves 30 Fortune 500 clients + 100 SMEs across 18 verticals (Auto, BFSI, Healthcare, Logistics). Deep client mining drives sticky revenue. Has a Netherlands subsidiary (NINtec Systems B.V.).
A5: 2. FY25 revenue surged 68% YoY to ₹139.8 Cr driven by new enterprise wins + cross-selling. 9M FY26 consolidated revenue ₹123.8 Cr, up 21.4% YoY — growth moderating from peak but still healthy double-digit.
A6: 3. Asset-light model: ROCE ~168%, ROE ~44%, D/E 0.03, Net cash ₹50 Cr. Minimal capex needs (~₹6 Cr on ₹140 Cr revenue). ~452 employees. Employee costs ~27-30% of revenue + subcontracting in Other Expenses.
A7: 4. Expanding into AI/ML, IoT, Cybersecurity SOCs, Blockchain — aligning with high-growth digital transformation themes. Multi-year contracts provide revenue visibility.
A8: 5. Key risks: Growth deceleration (9M FY26 PAT growth 23% vs FY25's 70%), small-cap with relatively low liquidity despite mainboard listing (migrated from SME to BSE/NSE mainboard in Feb 2023), nil dividend payout, client concentration risk, promoter-led (47.4%) with minimal institutional ownership.
A10: REVENUE GROWTH ASSUMPTIONS | B10: Year | C10: Growth Rate | D10: Rationale
A11: Revenue YoY Growth | B11: FY26E | C11: 0.22 | D11: 9M at 21.4% YoY run-rate; Q4 seasonal strength expected
B12: FY27E | C12: 0.2 | D12: Organic: new client wins + deeper penetration in Fortune 500 base; AI/ML ramp
B13: FY28E | C13: 0.18 | D13: Scale benefits; cybersecurity SOC + IoT contributions; gradual moderation
B14: FY29E | C14: 0.16 | D14: Maturing revenue base; industry CAGR ~15-18%; cross-sell stabilizes
B15: FY30E | C15: 0.14 | D15: Growth normalizing toward large IT services CAGR; base effect
B16: FY31E | C16: 0.12 | D16: Terminal normalization; India IT services long-term CAGR ~10-12%
A17: EMPLOYEE COST (% of Revenue) | D17: Historical: 27-31% of revenue; improving trend in FY26 (28.8% in Q3)
A18: Employee Cost % of Revenue | B18: FY26E | C18: 0.285 | D18: Improving utilization; 9M avg ~30.6%, Q3 dropped to 28.8%
B19: FY27E | C19: 0.28 | D19: Scale economies; higher revenue per employee as mix shifts to AI/ML
B20: FY28E | C20: 0.275 | D20: Offshore leverage; productivity gains from automation tools
B21: FY29E | C21: 0.275 | D21: Stabilized at optimal level; wage inflation offset by mix improvement
B22: FY30E | C22: 0.27 | D22: Continued scale; higher-value services reduce labor intensity
B23: FY31E | C23: 0.27 | D23: Steady-state efficiency level
A25: OTHER EXPENSES (% of Revenue) | D25: Historical: 44-48%; includes subcontracting, SaaS tools, travel, facilities
A26: Other Expenses % of Revenue | B26: FY26E | C26: 0.455 | D26: 9M trend ~44.8%; subcontracting mix + infra costs
B27: FY27E | C27: 0.45 | D27: Operating leverage kicks in; fixed cost absorption improves
B28: FY28E | C28: 0.445 | D28: Optimization of subcontracting vs in-house mix
B29: FY29E | C29: 0.44 | D29: Steady state; marginal improvements
B30: FY30E | C30: 0.44 | D30: Normalized; travel & facility costs proportional
B31: FY31E | C31: 0.435 | D31: Marginal improvement from scale
A33: OTHER P&L ASSUMPTIONS
A34: D&A (% of Revenue) | B34: All years | C34: 0.015 | D34: FY25 D&A was 1.5% of rev; asset-light model keeps this low
A36: Other Income (% of Revenue) | B36: All years | C36: 0.015 | D36: FY25: 1.6% of rev; interest on cash + treasury investments
A38: Effective Tax Rate | B38: All years | C38: 0.25 | D38: Q3 FY26: 25.6%; Hist avg ~25%; new tax regime steady state
A40: DCF VALUATION ASSUMPTIONS
A41: Risk-Free Rate (10Y GOI bond) | C41: 0.071 | D41: India 10Y Govt Bond yield ~7.1%
A42: Equity Risk Premium (India) | C42: 0.065 | D42: Damodaran India ERP for emerging market IT
A43: Beta (Unlevered) | C43: 1.15 | D43: Small-cap mainboard IT services; higher than large-cap IT avg of 0.9 due to size/liquidity premium
A44: Cost of Equity (Ke = Rf + β×ERP) | C44: =C41+C43*C42 -> 0.14575 | D44: CAPM model
A45: WACC (≈ Ke, near zero debt) | C45: =C44 -> 0.14575 | D45: Virtually no debt; WACC ≈ Cost of Equity
A46: Terminal Growth Rate (g) | C46: 0.05 | D46: India nominal GDP growth; IT co can sustain ~5% perpetuity
...

Sheet P&L
A1: NINtec Systems Ltd - Consolidated Profit & Loss Statement (₹ Cr)
A2: Particulars | B2: FY21A | C2: FY22A | D2: FY23A | E2: FY24A | F2: FY25A | G2: 9M FY26A | H2: FY26E | I2: FY27E | J2: FY28E | K2: FY29E | L2: FY30E | M2: FY31E
A3: Revenue from Operations | B3: 11.74 | C3: 17.3 | D3: 35 | E3: 83.05 | F3: 139.8 | G3: 123.8 | H3: =F3*(1+'Assumptions & Thesis'!C11) -> 170.556 | I3: =H3*(1+'Assumptions & Thesis'!C12) -> 204.6672 | J3: =I3*(1+'Assumptions & Thesis'!C13) -> 241.5073 | K3: =J3*(1+'Assumptions & Thesis'!C14) -> 280.14846 | L3: =K3*(1+'Assumptions & Thesis'!C15) -> 319.36925 | M3: =L3*(1+'Assumptions & Thesis'!C16) -> 357.69356
A4: YoY Growth % | C4: =(C3-B3)/B3 -> 0.47359455 | D4: =(D3-C3)/C3 -> 1.0231214 | E4: =(E3-D3)/D3 -> 1.3728571 | F4: =(F3-E3)/E3 -> 0.6833233 | H4: =(H3-F3)/F3 -> 0.22 | I4: =(I3-H3)/H3 -> 0.2 | J4: =(J3-I3)/I3 -> 0.18 | K4: =(K3-J3)/J3 -> 0.16 | L4: =(L3-K3)/K3 -> 0.14 | M4: =(M3-L3)/L3 -> 0.12
A6: Employee Benefit Expenses | B6: 4.8 | C6: 6.9 | D6: 9.5 | E6: 19.5 | F6: 37.8 | G6: 37.9 | H6: =H3*'Assumptions & Thesis'!C18 -> 48.60846 | I6: =I3*'Assumptions & Thesis'!C19 -> 57.306816 | J6: =J3*'Assumptions & Thesis'!C20 -> 66.414506 | K6: =K3*'Assumptions & Thesis'!C21 -> 77.040827 | L6: =L3*'Assumptions & Thesis'!C22 -> 86.229697 | M6: =M3*'Assumptions & Thesis'!C23 -> 96.577261
A7: Other Expenses | B7: 4.2 | C7: 6.1 | D7: 15.5 | E7: 39.6 | F7: 66.5 | G7: 55.5 | H7: =H3*'Assumptions & Thesis'!C26 -> 77.60298 | I7: =I3*'Assumptions & Thesis'!C27 -> 92.10024 | J7: =J3*'Assumptions & Thesis'!C28 -> 107.47075 | K7: =K3*'Assumptions & Thesis'!C29 -> 123.26532 | L7: =L3*'Assumptions & Thesis'!C30 -> 140.52247 | M7: =M3*'Assumptions & Thesis'!C31 -> 155.5967
A8: Total Operating Expenses | B8: =B6+B7 -> 9 | C8: =C6+C7 -> 13 | D8: =D6+D7 -> 25 | E8: =E6+E7 -> 59.1 | F8: =F6+F7 -> 104.3 | G8: =G6+G7 -> 93.4 | H8: =H6+H7 -> 126.21144 | I8: =I6+I7 -> 149.40706 | ... M8: =M6+M7 -> 252.17396
A10: EBITDA | B10: =B3-B8 -> 2.74 | C10: =C3-C8 -> 4.3 | D10: =D3-D8 -> 10 | E10: =E3-E8 -> 23.95 | F10: =F3-F8 -> 35.5 | G10: =G3-G8 -> 30.4 | H10: =H3-H8 -> 44.34456 | I10: =I3-I8 -> 55.260144 | ... M10: =M3-M8 -> 105.5196
A11: EBITDA Margin % | B11: =B10/B3 -> 0.23339012 | C11: =C10/C3 -> 0.24855491 | D11: =D10/D3 -> 0.28571429 | E11: =E10/E3 -> 0.28838049 | F11: =F10/F3 -> 0.25393419 | G11: =G10/G3 -> 0.24555735 | H11: =H10/H3 -> 0.26 | I11: =I10/I3 -> 0.27 | ... M11: =M10/M3 -> 0.295
A13: Depreciation & Amortization | B13: 0.3 | C13: 0.4 | D13: 0.6 | E13: 1.2 | F13: 2.1 | G13: 1.92 | H13: =H3*'Assumptions & Thesis'!C34 -> 2.55834 | I13: =I3*'Assumptions & Thesis'!C34 -> 3.070008 | J13: =J3*'Assumptions & Thesis'!C34 -> 3.6226094 | K13: =K3*'Assumptions & Thesis'!C34 -> 4.202227 | L13: =L3*'Assumptions & Thesis'!C34 -> 4.7905387 | M13: =M3*'Assumptions & Thesis'!C34 -> 5.3654034
A14: EBIT | B14: =B10-B13 -> 2.44 | C14: =C10-C13 -> 3.9 | D14: =D10-D13 -> 9.4 | E14: =E10-E13 -> 22.75 | F14: =F10-F13 -> 33.4 | G14: =G10-G13 -> 28.48 | H14: =H10-H13 -> 41.78622 | I14: =I10-I13 -> 52.190136 | ... M14: =M10-M13 -> 100.1542
A15: Interest Expense | B15: 0.1 | C15: 0.1 | D15: 0.15 | E15: 0.2 | F15: 0.25 | G15: 0.18 | H15: 0.25 | I15: 0.25 | J15: 0.25 | K15: 0.25 | L15: 0.25 | M15: 0.25
A16: Other Income | B16: 0.4 | C16: 0.5 | D16: 0.8 | E16: 1.5 | F16: 2.3 | G16: 1.8 | H16: =H3*'Assumptions & Thesis'!C36 -> 2.55834 | I16: =I3*'Assumptions & Thesis'!C36 -> 3.070008 | J16: =J3*'Assumptions & Thesis'!C36 -> 3.6226094 | K16: =K3*'Assumptions & Thesis'!C36 -> 4.202227 | L16: =L3*'Assumptions & Thesis'!C36 -> 4.7905387 | M16: =M3*'Assumptions & Thesis'!C36 -> 5.3654034
A17: Profit Before Tax (PBT) | B17: =B14-B15+B16 -> 2.74 | C17: =C14-C15+C16 -> 4.3 | D17: =D14-D15+D16 -> 10.05 | E17: =E14-E15+E16 -> 24.05 | F17: =F14-F15+F16 -> 35.45 | G17: =G14-G15+G16 -> 30.1 | H17: =H14-H15+H16 -> 44.09456 | I17: =I14-I15+I16 -> 55.010144 | ... M17: =M14-M15+M16 -> 105.2696
A18: Tax Expense | B18: =B17*'Assumptions & Thesis'!C38 -> 0.685 | C18: =C17*'Assumptions & Thesis'!C38 -> 1.075 | D18: =D17*'Assumptions & Thesis'!C38 -> 2.5125 | E18: =E17*'Assumptions & Thesis'!C38 -> 6.0125 | F18: =F17*'Assumptions & Thesis'!C38 -> 8.8625 | G18: =G17*'Assumptions & Thesis'!C38 -> 7.525 | H18: =H17*'Assumptions & Thesis'!C38 -> 11.02364 | I18: =I17*'Assumptions & Thesis'!C38 -> 13.752536 | J18: =J17*'Assumptions & Thesis'!C38 -> 16.843011 | K18: =K17*'Assumptions & Thesis'!C38 -> 19.898078 | L18: =L17*'Assumptions & Thesis'!C38 -> 23.09177 | M18: =M17*'Assumptions & Thesis'!C38 -> 26.3174
A20: Net Profit (PAT) | B20: =B17-B18 -> 2.055 | C20: =C17-C18 -> 3.225 | D20: =D17-D18 -> 7.5375 | E20: =E17-E18 -> 18.0375 | F20: =F17-F18 -> 26.5875 | G20: =G17-G18 -> 22.575 | H20: =H17-H18 -> 33.07092 | I20: =I17-I18 -> 41.257608 | ... M20: =M17-M18 -> 78.9522
A21: PAT Margin % | B21: =B20/B3 -> 0.17504259 | C21: =C20/C3 -> 0.18641618 | D21: =D20/D3 -> 0.21535714 | E21: =E20/E3 -> 0.21718844 | F21: =F20/F3 -> 0.1901824 | G21: =G20/G3 -> 0.18235057 | H21: =H20/H3 -> 0.19390065 | I21: =I20/I3 -> 0.20158388 | ... M21: =M20/M3 -> 0.22072581
A22: EPS (₹) | B22: =B20/1.858 -> 1.106028 | C22: =C20/1.858 -> 1.7357374 | D22: =D20/1.858 -> 4.0567815 | E22: =E20/1.858 -> 9.7080194 | F22: =F20/1.858 -> 14.309742 | G22: =G20/1.858 -> 12.150161 | H22: =H20/1.858 -> 17.799203 | I22: =I20/1.858 -> 22.205386 | ... M22: =M20/1.858 -> 42.493111

Sheet Balance Sheet
A1: NINtec Systems Ltd - Consolidated Balance Sheet (₹ Cr)
A2: Particulars | B2: FY23A | C2: FY24A | D2: FY25A | E2: FY26E | F2: FY27E | G2: FY28E | H2: FY29E | I2: FY30E
A3: EQUITY & LIABILITIES
A4: Share Capital | B4: 1.86 | C4: 1.86 | D4: 1.86 | E4: 1.86 | F4: 1.86 | G4: 1.86 | H4: 1.86 | I4: 1.86
A5: Reserves & Surplus | B5: 20.5 | C5: 34.5 | D5: 59.49 | E5: =D5+'P&L'!H20 -> 92.56092 | F5: =E5+'P&L'!I20 -> 133.81853 | G5: =F5+'P&L'!J20 -> 184.34756 | H5: =G5+'P&L'!K20 -> 244.04179 | I5: =H5+'P&L'!L20 -> 313.31711
A6: Total Shareholders' Equity | B6: =B4+B5 -> 22.36 | C6: =C4+C5 -> 36.36 | D6: =D4+D5 -> 61.35 | E6: =E4+E5 -> 94.42092 | F6: =F4+F5 -> 135.67853 | G6: =G4+G5 -> 186.20756 | H6: =H4+H5 -> 245.90179 | I6: =I4+I5 -> 315.17711
A7: Long-Term Borrowings | B7: 1.5 | C7: 1.8 | D7: 2.11 | E7: 2 | F7: 1.8 | G7: 1.5 | H7: 1.2 | I7: 1
A8: Current Liabilities | B8: 12.5 | C8: 33 | D8: 48.95 | E8: ='P&L'!H3*0.28 -> 47.75568 | F8: ='P&L'!I3*0.28 -> 57.306816 | G8: ='P&L'!J3*0.27 -> 65.20697 | H8: ='P&L'!K3*0.27 -> 75.640085 | I8: ='P&L'!L3*0.27 -> 86.229697
A9: Total Liabilities & Equity | B9: =B6+B7+B8 -> 36.36 | C9: =C6+C7+C8 -> 71.16 | D9: =D6+D7+D8 -> 112.41 | E9: =E6+E7+E8 -> 144.1766 | F9: =F6+F7+F8 -> 194.78534 | G9: =G6+G7+G8 -> 252.91453 | H9: =H6+H7+H8 -> 322.74188 | I9: =I6+I7+I8 -> 402.4068
A11: ASSETS
A12: Fixed Assets (Net) | B12: 3.5 | C12: 5.2 | D12: 7.39 | E12: =D12+'P&L'!H3*'Assumptions & Thesis'!C49-'P&L'!H13 -> 10.80112 | F12: =E12+'P&L'!I3*'Assumptions & Thesis'!C49-'P&L'!I13 -> 14.894464 | G12: =F12+'P&L'!J3*'Assumptions & Thesis'!C49-'P&L'!J13 -> 19.72461 | H12: =G12+'P&L'!K3*'Assumptions & Thesis'!C49-'P&L'!K13 -> 25.327579 | I12: =H12+'P&L'!L3*'Assumptions & Thesis'!C49-'P&L'!L13 -> 31.714964
A13: Other Non-Current Assets | B13: 2.5 | C13: 4 | D13: 5 | E13: 5.5 | F13: 6 | G13: 6.5 | H13: 7 | I13: 7.5
A14: Current Assets | B14: 29 | C14: 60 | D14: 105.19 | E14: =E9-E12-E13 -> 127.87548 | F14: =F9-F12-F13 -> 173.89088 | G14: =G9-G12-G13 -> 226.68992 | H14: =H9-H12-H13 -> 290.4143 | I14: =I9-I12-I13 -> 363.19184
A15: Total Assets | B15: =B12+B13+B14 -> 35 | C15: =C12+C13+C14 -> 69.2 | D15: =D12+D13+D14 -> 117.58 | E15: =E12+E13+E14 -> 144.1766 | F15: =F12+F13+F14 -> 194.78534 | G15: =G12+G13+G14 -> 252.91453 | H15: =H12+H13+H14 -> 322.74188 | I15: =I12+I13+I14 -> 402.4068
A17: KEY RATIOS
A18: ROE % | B18: ='P&L'!D20/B6 -> 0.3370975 | C18: ='P&L'!E20/C6 -> 0.49608086 | D18: ='P&L'!F20/D6 -> 0.43337408 | E18: ='P&L'!H20/E6 -> 0.35024992 | F18: ='P&L'!I20/F6 -> 0.30408355 | G18: ='P&L'!J20/G6 -> 0.27135865 | H18: ='P&L'!K20/H6 -> 0.2427564 | I18: ='P&L'!L20/I6 -> 0.21979804
A19: Debt/Equity | B19: =B7/B6 -> 0.067084079 | C19: =C7/C6 -> 0.04950495 | D19: =D7/D6 -> 0.034392828 | E19: =E7/E6 -> 0.021181747 | F19: =F7/F6 -> 0.013266653 | G19: =G7/G6 -> 0.0080555268 | H19: =H7/H6 -> 0.0048799969 | I19: =I7/I6 -> 0.0031728193
A20: Current Ratio | B20: =B14/B8 -> 2.32 | C20: =C14/C8 -> 1.8181818 | D20: =D14/D8 -> 2.1489275 | E20: =E14/E8 -> 2.677702 | F20: =F14/F8 -> 3.0343839 | G20: =G14/G8 -> 3.4764676 | H20: =H14/H8 -> 3.8394232 | I20: =I14/I8 -> 4.2119113

Sheet Cash Flow
A1: NINtec Systems Ltd - Free Cash Flow Build (₹ Cr)
A2: Particulars | B2: FY23A | C2: FY24A | D2: FY25A | E2: FY26E | F2: FY27E | G2: FY28E | H2: FY29E | I2: FY30E
A3: EBIT | B3: ='P&L'!D14 -> 9.4 | C3: ='P&L'!E14 -> 22.75 | D3: ='P&L'!F14 -> 33.4 | E3: ='P&L'!H14 -> 41.78622 | F3: ='P&L'!I14 -> 52.190136 | G3: ='P&L'!J14 -> 63.999433 | H3: ='P&L'!K14 -> 75.640085 | I3: ='P&L'!L14 -> 87.826543
A4: (-) Tax on EBIT | B4: =-B3*'Assumptions & Thesis'!C38 -> -2.35 | C4: =-C3*'Assumptions & Thesis'!C38 -> -5.6875 | D4: =-D3*'Assumptions & Thesis'!C38 -> -8.35 | E4: =-E3*'Assumptions & Thesis'!C38 -> -10.446555 | F4: =-F3*'Assumptions & Thesis'!C38 -> -13.047534 | G4: =-G3*'Assumptions & Thesis'!C38 -> -15.999858 | H4: =-H3*'Assumptions & Thesis'!C38 -> -18.910021 | I4: =-I3*'Assumptions & Thesis'!C38 -> -21.956636
A5: NOPAT | B5: =B3+B4 -> 7.05 | C5: =C3+C4 -> 17.0625 | D5: =D3+D4 -> 25.05 | E5: =E3+E4 -> 31.339665 | F5: =F3+F4 -> 39.142602 | G5: =G3+G4 -> 47.999575 | H5: =H3+H4 -> 56.730064 | I5: =I3+I4 -> 65.869907
A6: (+) Depreciation & Amortization | B6: ='P&L'!D13 -> 0.6 | C6: ='P&L'!E13 -> 1.2 | D6: ='P&L'!F13 -> 2.1 | E6: ='P&L'!H13 -> 2.55834 | F6: ='P&L'!I13 -> 3.070008 | G6: ='P&L'!J13 -> 3.6226094 | H6: ='P&L'!K13 -> 4.202227 | I6: ='P&L'!L13 -> 4.7905387
A7: (-) Capex | B7: -2 | C7: -3.5 | D7: -6 | E7: =-'P&L'!H3*'Assumptions & Thesis'!C49 -> -5.96946 | F7: =-'P&L'!I3*'Assumptions & Thesis'!C49 -> -7.163352 | G7: =-'P&L'!J3*'Assumptions & Thesis'!C49 -> -8.4527554 | H7: =-'P&L'!K3*'Assumptions & Thesis'!C49 -> -9.8051962 | I7: =-'P&L'!L3*'Assumptions & Thesis'!C49 -> -11.177924
A8: (-) Change in Working Capital | B8: -4 | C8: -10 | D8: -12 | E8: =-('P&L'!H3-F3)*'Assumptions & Thesis'!C50/365 -> -29.186103 | F8: =-('P&L'!I3-'P&L'!H3)*'Assumptions & Thesis'!C50/365 -> -8.4109808 | G8: =-('P&L'!J3-'P&L'!I3)*'Assumptions & Thesis'!C50/365 -> -9.0838593 | H8: =-('P&L'!K3-'P&L'!J3)*'Assumptions & Thesis'!C50/365 -> -9.5279591 | I8: =-('P&L'!L3-'P&L'!K3)*'Assumptions & Thesis'!C50/365 -> -9.6708785
A10: Free Cash Flow (FCFF) | B10: =B5+B6+B7+B8 -> 1.65 | C10: =C5+C6+C7+C8 -> 4.7625 | D10: =D5+D6+D7+D8 -> 9.15 | E10: =E5+E6+E7+E8 -> -1.2575585 | F10: =F5+F6+F7+F8 -> 26.638277 | G10: =G5+G6+G7+G8 -> 34.08557 | H10: =H5+H6+H7+H8 -> 41.599135 | I10: =I5+I6+I7+I8 -> 49.811644
A11: FCFF Margin % | B11: =B10/'P&L'!D3 -> 0.047142857 | C11: =C10/'P&L'!E3 -> 0.057344973 | D11: =D10/'P&L'!F3 -> 0.065450644 | E11: =E10/'P&L'!H3 -> -0.0073732877 | F11: =F10/'P&L'!I3 -> 0.13015411 | G11: =G10/'P&L'!J3 -> 0.14113681 | H11: =H10/'P&L'!K3 -> 0.14848961 | I11: =I10/'P&L'!L3 -> 0.15596882
A13: FCFF per Share (₹) | B13: =B10/'Assumptions & Thesis'!C52 -> 0.88805167 | C13: =C10/'Assumptions & Thesis'!C52 -> 2.56324 | D13: =D10/'Assumptions & Thesis'!C52 -> 4.9246502 | E13: =E10/'Assumptions & Thesis'!C52 -> -0.67683447 | F13: =F10/'Assumptions & Thesis'!C52 -> 14.337071 | G13: =G10/'Assumptions & Thesis'!C52 -> 18.345301 | H13: =H10/'Assumptions & Thesis'!C52 -> 22.389201 | I13: =I10/'Assumptions & Thesis'!C52 -> 26.809281

Sheet DCF Valuation
A1: NINtec Systems Ltd - DCF Valuation
A3: DCF INPUTS (from Assumptions)
A4: WACC | B4: ='Assumptions & Thesis'!C45 -> 0.14575
A5: Terminal Growth Rate | B5: ='Assumptions & Thesis'!C46 -> 0.05
A6: Shares Outstanding (Cr) | B6: ='Assumptions & Thesis'!C52 -> 1.858
A7: Net Debt (₹ Cr) | B7: ='Assumptions & Thesis'!C51 -> -50.22
A8: CMP (₹) | B8: ='Assumptions & Thesis'!C53 -> 324
A10: PROJECTED FREE CASH FLOWS | B10: FY27E | C10: FY28E | D10: FY29E | E10: FY30E | F10: FY31E
A11: FCFF (₹ Cr) | B11: ='Cash Flow'!F10 -> 26.638277 | C11: ='Cash Flow'!G10 -> 34.08557 | D11: ='Cash Flow'!H10 -> 41.599135 | E11: ='Cash Flow'!I10 -> 49.811644 | F11: =E11*(1+'Assumptions & Thesis'!C16) -> 55.789041
A12: Discount Period | B12: 1 | C12: 2 | D12: 3 | E12: 4 | F12: 5
A13: Discount Factor | B13: =1/(1+$B$4)^B12 -> 0.87279075 | C13: =1/(1+$B$4)^C12 -> 0.76176369 | D13: =1/(1+$B$4)^D12 -> 0.6648603 | E13: =1/(1+$B$4)^E12 -> 0.58028392 | F13: =1/(1+$B$4)^F12 -> 0.50646644
A14: PV of FCFF | B14: =B11*B13 -> 23.249642 | C14: =C11*C13 -> 25.965149 | D14: =D11*D13 -> 27.657614 | E14: =E11*E13 -> 28.904896 | F14: =F11*F13 -> 28.255277
A16: TERMINAL VALUE CALCULATION
A17: Terminal Year FCFF (FY31E) | B17: =F11 -> 55.789041
A18: Terminal Value = FCFF×(1+g)/(WACC-g) | B18: =B17*(1+B5)/(B4-B5) -> 611.78583
A19: PV of Terminal Value | B19: =B18*F13 -> 309.84899
A21: VALUATION SUMMARY
A22: Sum of PV of FCFFs | B22: =SUM(B14:F14) -> 134.03258
A23: PV of Terminal Value | B23: =B19 -> 309.84899
A24: Enterprise Value | B24: =B22+B23 -> 443.88157
A25: (-) Net Debt (Add Net Cash) | B25: =-B7 -> 50.22 | C25: (+ve because net cash)
A26: Equity Value (₹ Cr) | B26: =B24+B25 -> 494.10157
A27: Implied Share Price (₹) | B27: =B26/B6 -> 265.93195
A28: CMP (₹) | B28: =B8 -> 324
A29: Upside / (Downside) | B29: =(B27-B28)/B28 -> -0.17922237
A32: SENSITIVITY ANALYSIS: Implied Share Price (₹) [WACC vs Terminal Growth Rate]
A33: WACC\TGR | B33: 0.03 | C33: 0.04 | D33: 0.045 | E33: 0.05 | F33: 0.055 | G33: 0.06 | H33: 0.07
A34: 0.12 | B34: =($B$11/(1+$A34)^1+$C$11/(1+$A34)^2+$D$11/(1+$A34)^3+$E$11/(1+$A34)^4+$F$11/(1+$A34)^5+($F$11*(1+B$33)/($A34-B$33))/(1+$A34)^5+$B$25)/$B$6 -> 299.4545 | C34: =($B$11/(1+$A34)^1+$C$11/(1+$A34)^2+$D$11/(1+$A34)^3+$E$11/(1+$A34)^4+$F$11/(1+$A34)^5+($F$11*(1+C$33)/($A34-C$33))/(1+$A34)^5+$B$25)/$B$6 -> 325.95771 | D34: =($B$11/(1+$A34)^1+$C$11/(1+$A34)^2+$D$11/(1+$A34)^3+$E$11/(1+$A34)^4+$F$11/(1+$A34)^5+($F$11*(1+D$33)/($A34-D$33))/(1+$A34)^5+$B$25)/$B$6 -> 341.85964 | E34: =($B$11/(1+$A34)^1+$C$11/(1+$A34)^2+$D$11/(1+$A34)^3+$E$11/(1+$A34)^4+$F$11/(1+$A34)^5+($F$11*(1+E$33)/($A34-E$33))/(1+$A34)^5+$B$25)/$B$6 -> 360.03328 | F34: =($B$11/(1+$A34)^1+$C$11/(1+$A34)^2+$D$11/(1+$A34)^3+$E$11/(1+$A34)^4+$F$11/(1+$A34)^5+($F$11*(1+F$33)/($A34-F$33))/(1+$A34)^5+$B$25)/$B$6 -> 381.00286 | G34: =($B$11/(1+$A34)^1+$C$11/(1+$A34)^2+$D$11/(1+$A34)^3+$E$11/(1+$A34)^4+$F$11/(1+$A34)^5+($F$11*(1+G$33)/($A34-G$33))/(1+$A34)^5+$B$25)/$B$6 -> 405.46737 | H34: =($B$11/(1+$A34)^1+$C$11/(1+$A34)^2+$D$11/(1+$A34)^3+$E$11/(1+$A34)^4+$F$11/(1+$A34)^5+($F$11*(1+H$33)/($A34-H$33))/(1+$A34)^5+$B$25)/$B$6 -> 469.07509
A35: 0.13 | B35: =($B$11/(1+$A35)^1+$C$11/(1+$A35)^2+$D$11/(1+$A35)^3+$E$11/(1+$A35)^4+$F$11/(1+$A35)^5+($F$11*(1+B$33)/($A35-B$33))/(1+$A35)^5+$B$25)/$B$6 -> 270.20077 | C35: =($B$11/(1+$A35)^1+$C$11/(1+$A35)^2+$D$11/(1+$A35)^3+$E$11/(1+$A35)^4+$F$11/(1+$A35)^5+($F$11*(1+C$33)/($A35-C$33))/(1+$A35)^5+$B$25)/$B$6 -> 290.66272 | D35: =($B$11/(1+$A35)^1+$C$11/(1+$A35)^2+$D$11/(1+$A35)^3+$E$11/(1+$A35)^4+$F$11/(1+$A35)^5+($F$11*(1+D$33)/($A35-D$33))/(1+$A35)^5+$B$25)/$B$6 -> 302.69916 | E35: =($B$11/(1+$A35)^1+$C$11/(1+$A35)^2+$D$11/(1+$A35)^3+$E$11/(1+$A35)^4+$F$11/(1+$A35)^5+($F$11*(1+E$33)/($A35-E$33))/(1+$A35)^5+$B$25)/$B$6 -> 316.24015 | F35: =($B$11/(1+$A35)^1+$C$11/(1+$A35)^2+$D$11/(1+$A35)^3+$E$11/(1+$A35)^4+$F$11/(1+$A35)^5+($F$11*(1+F$33)/($A35-F$33))/(1+$A35)^5+$B$25)/$B$6 -> 331.58661 | G35: =($B$11/(1+$A35)^1+$C$11/(1+$A35)^2+$D$11/(1+$A35)^3+$E$11/(1+$A35)^4+$F$11/(1+$A35)^5+($F$11*(1+G$33)/($A35-G$33))/(1+$A35)^5+$B$25)/$B$6 -> 349.12542 | H35: =($B$11/(1+$A35)^1+$C$11/(1+$A35)^2+$D$11/(1+$A35)^3+$E$11/(1+$A35)^4+$F$11/(1+$A35)^5+($F$11*(1+H$33)/($A35-H$33))/(1+$A35)^5+$B$25)/$B$6 -> 392.97244
A36: 0.14 | B36: =($B$11/(1+$A36)^1+$C$11/(1+$A36)^2+$D$11/(1+$A36)^3+$E$11/(1+$A36)^4+$F$11/(1+$A36)^5+($F$11*(1+B$33)/($A36-B$33))/(1+$A36)^5+$B$25)/$B$6 -> 246.32538 | C36: =($B$11/(1+$A36)^1+$C$11/(1+$A36)^2+$D$11/(1+$A36)^3+$E$11/(1+$A36)^4+$F$11/(1+$A36)^5+($F$11*(1+C$33)/($A36-C$33))/(1+$A36)^5+$B$25)/$B$6 -> 262.48724 | D36: =($B$11/(1+$A36)^1+$C$11/(1+$A36)^2+$D$11/(1+$A36)^3+$E$11/(1+$A36)^4+$F$11/(1+$A36)^5+($F$11*(1+D$33)/($A36-D$33))/(1+$A36)^5+$B$25)/$B$6 -> 271.8441 | E36: =($B$11/(1+$A36)^1+$C$11/(1+$A36)^2+$D$11/(1+$A36)^3+$E$11/(1+$A36)^4+$F$11/(1+$A36)^5+($F$11*(1+E$33)/($A36-E$33))/(1+$A36)^5+$B$25)/$B$6 -> 282.24061 | F36: =($B$11/(1+$A36)^1+$C$11/(1+$A36)^2+$D$11/(1+$A36)^3+$E$11/(1+$A36)^4+$F$11/(1+$A36)^5+($F$11*(1+F$33)/($A36-F$33))/(1+$A36)^5+$B$25)/$B$6 -> 293.86024 | G36: =($B$11/(1+$A36)^1+$C$11/(1+$A36)^2+$D$11/(1+$A36)^3+$E$11/(1+$A36)^4+$F$11/(1+$A36)^5+($F$11*(1+G$33)/($A36-G$33))/(1+$A36)^5+$B$25)/$B$6 -> 306.93233 | H36: =($B$11/(1+$A36)^1+$C$11/(1+$A36)^2+$D$11/(1+$A36)^3+$E$11/(1+$A36)^4+$F$11/(1+$A36)^5+($F$11*(1+H$33)/($A36-H$33))/(1+$A36)^5+$B$25)/$B$6 -> 338.67882
A37: 0.14575 | B37: =($B$11/(1+$A37)^1+$C$11/(1+$A37)^2+$D$11/(1+$A37)^3+$E$11/(1+$A37)^4+$F$11/(1+$A37)^5+($F$11*(1+B$33)/($A37-B$33))/(1+$A37)^5+$B$25)/$B$6 -> 234.48968 | C37: =($B$11/(1+$A37)^1+$C$11/(1+$A37)^2+$D$11/(1+$A37)^3+$E$11/(1+$A37)^4+$F$11/(1+$A37)^5+($F$11*(1+C$33)/($A37-C$33))/(1+$A37)^5+$B$25)/$B$6 -> 248.72418 | D37: =($B$11/(1+$A37)^1+$C$11/(1+$A37)^2+$D$11/(1+$A37)^3+$E$11/(1+$A37)^4+$F$11/(1+$A37)^5+($F$11*(1+D$33)/($A37-D$33))/(1+$A37)^5+$B$25)/$B$6 -> 256.90108 | E37: =($B$11/(1+$A37)^1+$C$11/(1+$A37)^2+$D$11/(1+$A37)^3+$E$11/(1+$A37)^4+$F$11/(1+$A37)^5+($F$11*(1+E$33)/($A37-E$33))/(1+$A37)^5+$B$25)/$B$6 -> 265.93195 | F37: =($B$11/(1+$A37)^1+$C$11/(1+$A37)^2+$D$11/(1+$A37)^3+$E$11/(1+$A37)^4+$F$11/(1+$A37)^5+($F$11*(1+F$33)/($A37-F$33))/(1+$A37)^5+$B$25)/$B$6 -> 275.95797 | G37: =($B$11/(1+$A37)^1+$C$11/(1+$A37)^2+$D$11/(1+$A37)^3+$E$11/(1+$A37)^4+$F$11/(1+$A37)^5+($F$11*(1+G$33)/($A37-G$33))/(1+$A37)^5+$B$25)/$B$6 -> 287.1532 | H37: =($B$11/(1+$A37)^1+$C$11/(1+$A37)^2+$D$11/(1+$A37)^3+$E$11/(1+$A37)^4+$F$11/(1+$A37)^5+($F$11*(1+H$33)/($A37-H$33))/(1+$A37)^5+$B$25)/$B$6 -> 313.97741
A38: 0.155 | B38: =($B$11/(1+$A38)^1+$C$11/(1+$A38)^2+$D$11/(1+$A38)^3+$E$11/(1+$A38)^4+$F$11/(1+$A38)^5+($F$11*(1+B$33)/($A38-B$33))/(1+$A38)^5+$B$25)/$B$6 -> 217.76814 | C38: =($B$11/(1+$A38)^1+$C$11/(1+$A38)^2+$D$11/(1+$A38)^3+$E$11/(1+$A38)^4+$F$11/(1+$A38)^5+($F$11*(1+C$33)/($A38-C$33))/(1+$A38)^5+$B$25)/$B$6 -> 229.50542 | D38: =($B$11/(1+$A38)^1+$C$11/(1+$A38)^2+$D$11/(1+$A38)^3+$E$11/(1+$A38)^4+$F$11/(1+$A38)^5+($F$11*(1+D$33)/($A38-D$33))/(1+$A38)^5+$B$25)/$B$6 -> 236.17433 | E38: =($B$11/(1+$A38)^1+$C$11/(1+$A38)^2+$D$11/(1+$A38)^3+$E$11/(1+$A38)^4+$F$11/(1+$A38)^5+($F$11*(1+E$33)/($A38-E$33))/(1+$A38)^5+$B$25)/$B$6 -> 243.47837 | F38: =($B$11/(1+$A38)^1+$C$11/(1+$A38)^2+$D$11/(1+$A38)^3+$E$11/(1+$A38)^4+$F$11/(1+$A38)^5+($F$11*(1+F$33)/($A38-F$33))/(1+$A38)^5+$B$25)/$B$6 -> 251.51282 | G38: =($B$11/(1+$A38)^1+$C$11/(1+$A38)^2+$D$11/(1+$A38)^3+$E$11/(1+$A38)^4+$F$11/(1+$A38)^5+($F$11*(1+G$33)/($A38-G$33))/(1+$A38)^5+$B$25)/$B$6 -> 260.393 | H38: =($B$11/(1+$A38)^1+$C$11/(1+$A38)^2+$D$11/(1+$A38)^3+$E$11/(1+$A38)^4+$F$11/(1+$A38)^5+($F$11*(1+H$33)/($A38-H$33))/(1+$A38)^5+$B$25)/$B$6 -> 281.28753
A39: 0.17 | B39: =($B$11/(1+$A39)^1+$C$11/(1+$A39)^2+$D$11/(1+$A39)^3+$E$11/(1+$A39)^4+$F$11/(1+$A39)^5+($F$11*(1+B$33)/($A39-B$33))/(1+$A39)^5+$B$25)/$B$6 -> 195.42459 | C39: =($B$11/(1+$A39)^1+$C$11/(1+$A39)^2+$D$11/(1+$A39)^3+$E$11/(1+$A39)^4+$F$11/(1+$A39)^5+($F$11*(1+C$33)/($A39-C$33))/(1+$A39)^5+$B$25)/$B$6 -> 204.22875 | D39: =($B$11/(1+$A39)^1+$C$11/(1+$A39)^2+$D$11/(1+$A39)^3+$E$11/(1+$A39)^4+$F$11/(1+$A39)^5+($F$11*(1+D$33)/($A39-D$33))/(1+$A39)^5+$B$25)/$B$6 -> 209.15909 | E39: =($B$11/(1+$A39)^1+$C$11/(1+$A39)^2+$D$11/(1+$A39)^3+$E$11/(1+$A39)^4+$F$11/(1+$A39)^5+($F$11*(1+E$33)/($A39-E$33))/(1+$A39)^5+$B$25)/$B$6 -> 214.50028 | F39: =($B$11/(1+$A39)^1+$C$11/(1+$A39)^2+$D$11/(1+$A39)^3+$E$11/(1+$A39)^4+$F$11/(1+$A39)^5+($F$11*(1+F$33)/($A39-F$33))/(1+$A39)^5+$B$25)/$B$6 -> 220.30593 | G39: =($B$11/(1+$A39)^1+$C$11/(1+$A39)^2+$D$11/(1+$A39)^3+$E$11/(1+$A39)^4+$F$11/(1+$A39)^5+($F$11*(1+G$33)/($A39-G$33))/(1+$A39)^5+$B$25)/$B$6 -> 226.63937 | H39: =($B$11/(1+$A39)^1+$C$11/(1+$A39)^2+$D$11/(1+$A39)^3+$E$11/(1+$A39)^4+$F$11/(1+$A39)^5+($F$11*(1+H$33)/($A39-H$33))/(1+$A39)^5+$B$25)/$B$6 -> 241.20626
A40: 0.19 | B40: =($B$11/(1+$A40)^1+$C$11/(1+$A40)^2+$D$11/(1+$A40)^3+$E$11/(1+$A40)^4+$F$11/(1+$A40)^5+($F$11*(1+B$33)/($A40-B$33))/(1+$A40)^5+$B$25)/$B$6 -> 172.26954 | C40: =($B$11/(1+$A40)^1+$C$11/(1+$A40)^2+$D$11/(1+$A40)^3+$E$11/(1+$A40)^4+$F$11/(1+$A40)^5+($F$11*(1+C$33)/($A40-C$33))/(1+$A40)^5+$B$25)/$B$6 -> 178.50838 | D40: =($B$11/(1+$A40)^1+$C$11/(1+$A40)^2+$D$11/(1+$A40)^3+$E$11/(1+$A40)^4+$F$11/(1+$A40)^5+($F$11*(1+D$33)/($A40-D$33))/(1+$A40)^5+$B$25)/$B$6 -> 181.9505 | E40: =($B$11/(1+$A40)^1+$C$11/(1+$A40)^2+$D$11/(1+$A40)^3+$E$11/(1+$A40)^4+$F$11/(1+$A40)^5+($F$11*(1+E$33)/($A40-E$33))/(1+$A40)^5+$B$25)/$B$6 -> 185.63849 | F40: =($B$11/(1+$A40)^1+$C$11/(1+$A40)^2+$D$11/(1+$A40)^3+$E$11/(1+$A40)^4+$F$11/(1+$A40)^5+($F$11*(1+F$33)/($A40-F$33))/(1+$A40)^5+$B$25)/$B$6 -> 189.59966 | G40: =($B$11/(1+$A40)^1+$C$11/(1+$A40)^2+$D$11/(1+$A40)^3+$E$11/(1+$A40)^4+$F$11/(1+$A40)^5+($F$11*(1+G$33)/($A40-G$33))/(1+$A40)^5+$B$25)/$B$6 -> 193.86554 | H40: =($B$11/(1+$A40)^1+$C$11/(1+$A40)^2+$D$11/(1+$A40)^3+$E$11/(1+$A40)^4+$F$11/(1+$A40)^5+($F$11*(1+H$33)/($A40-H$33))/(1+$A40)^5+$B$25)/$B$6 -> 203.46376

Sheet Comparable Valuation
A1: NINtec Systems Ltd - Comparable Company Analysis
A3: PEER COMPARISON TABLE
A4: Company | B4: Mkt Cap (₹ Cr) | C4: Revenue (₹ Cr) | D4: PAT (₹ Cr) | E4: P/E (TTM) | F4: EV/EBITDA | G4: P/B | H4: PAT Margin | I4: Rev CAGR (3Y)
A5: NINtec Systems | B5: 602 | C5: 166 | D5: 28.2 | E5: 28.8 | F5: 23.3 | G5: 12.3 | H5: 0.187 | I5: 0.68
A6: Silver Touch Technologies | B6: 1632 | C6: 331 | D6: 31.7 | E6: 56.1 | F6: 25 | G6: 11.2 | H6: 0.096 | I6: 0.25
A7: Onward Technologies | B7: 1350 | C7: 620 | D7: 45 | E7: 30 | F7: 18 | G7: 7.5 | H7: 0.073 | I7: 0.15
A8: Iris Business Services | B8: 800 | C8: 150 | D8: 18 | E8: 44.4 | F8: 32 | G8: 15 | H8: 0.12 | I8: 0.22
A9: Subex Ltd | B9: 1200 | C9: 350 | D9: 30 | E9: 40 | F9: 22 | G9: 8 | H9: 0.086 | I9: 0.12
A10: Allied Digital Services | B10: 900 | C10: 600 | D10: 35 | E10: 25.7 | F10: 15 | G10: 5 | H10: 0.058 | I10: 0.1
A12: Peer Median (ex-NINtec) | B12: =MEDIAN(B6:B10) -> 1200 | C12: =MEDIAN(C6:C10) -> 350 | D12: =MEDIAN(D6:D10) -> 31.7 | E12: =MEDIAN(E6:E10) -> 40 | F12: =MEDIAN(F6:F10) -> 22 | G12: =MEDIAN(G6:G10) -> 8 | H12: =MEDIAN(H6:H10) -> 0.086 | I12: =MEDIAN(I6:I10) -> 0.15
A13: Peer Average (ex-NINtec) | B13: =AVERAGE(B6:B10) -> 1176.4 | C13: =AVERAGE(C6:C10) -> 410.2 | D13: =AVERAGE(D6:D10) -> 31.94 | E13: =AVERAGE(E6:E10) -> 39.24 | F13: =AVERAGE(F6:F10) -> 22.4 | G13: =AVERAGE(G6:G10) -> 9.34 | H13: =AVERAGE(H6:H10) -> 0.0866 | I13: =AVERAGE(I6:I10) -> 0.168
A15: RELATIVE VALUATION - IMPLIED PRICE (₹)
A16: Method | B16: Peer Median Multiple | C16: NINtec FY27E Metric | D16: Implied Mkt Cap (₹ Cr) | E16: Implied Price (₹)
A17: P/E (FY27E) | B17: =E12 -> 40 | C17: ='P&L'!I20 -> 41.257608 | D17: =B17*C17 -> 1650.3043 | E17: =D17/'Assumptions & Thesis'!C52 -> 888.21546
A18: EV/EBITDA (FY27E) | B18: =F12 -> 22 | C18: ='P&L'!I10 -> 55.260144 | D18: =B18*C18+'Assumptions & Thesis'!C51 -> 1165.5032 | E18: =D18/'Assumptions & Thesis'!C52 -> 627.28911
A20: VALUATION FOOTBALL FIELD SUMMARY
A21: Method | B21: Implied Price (₹) | C21: vs CMP of ₹324 | D21: Verdict
A22: DCF (Base Case) | B22: ='DCF Valuation'!B27 -> 265.93195 | C22: =(B22-'Assumptions & Thesis'!C53)/'Assumptions & Thesis'!C53 -> -0.17922237 | D22: =IF(C22>0.1,"UPSIDE",IF(C22<-0.1,"DOWNSIDE","FAIR")) -> DOWNSIDE
A23: Peer P/E Comps (FY27E) | B23: =E17 -> 888.21546 | C23: =(B23-'Assumptions & Thesis'!C53)/'Assumptions & Thesis'!C53 -> 1.7414057 | D23: =IF(C23>0.1,"UPSIDE",IF(C23<-0.1,"DOWNSIDE","FAIR")) -> UPSIDE
A24: Peer EV/EBITDA Comps (FY27E) | B24: =E18 -> 627.28911 | C24: =(B24-'Assumptions & Thesis'!C53)/'Assumptions & Thesis'!C53 -> 0.9360775 | D24: =IF(C24>0.1,"UPSIDE",IF(C24<-0.1,"DOWNSIDE","FAIR")) -> UPSIDE
A26: NOTE: Peer comps suggest NINtec trades at a significant discount to peers on FY27E earnings. This reflects:
A27: (a) Micro-cap liquidity discount, (b) Lower institutional ownership, (c) Growth deceleration from FY25 peak, (d) Higher execution risk at scale. The DCF provides a more conservative and realistic base-case valuation.
A29: BLENDED FAIR VALUE PER SHARE
A30: Method | B30: Implied Price (₹) | C30: Weight | D30: Weighted Value (₹) | E30: Rationale for Weight
A31: DCF (Base Case) | B31: =B22 -> 265.93195 | C31: 0.5 | D31: =B31*C31 -> 132.96598 | E31: Most rigorous; company-specific FCFs; less distorted by peer noise
A32: Peer EV/EBITDA (FY27E) | B32: =B24 -> 627.28911 | C32: 0.3 | D32: =B32*C32 -> 188.18673 | E32: EV/EBITDA less sensitive to capital structure; relevant for asset-light IT
A33: Peer P/E (FY27E) | B33: =B23 -> 888.21546 | C33: 0.2 | D33: =B33*C33 -> 177.64309 | E33: Peer P/Es inflated (~40x median); applied at lower weight
A34: Weight Check | C34: =SUM(C31:C33) -> 1
A36: Blended Fair Value (₹/share) | D36: =SUM(D31:D33) -> 498.7958
A37: CMP (₹) | D37: ='Assumptions & Thesis'!C53 -> 324
A38: Upside / (Downside) to CMP | D38: =(D36-D37)/D37 -> 0.53949321
